Workbook
Name Calendar: Calendar!$A$2:$G$27
Name CalendarEventNumbers: Calendar!$A$2:$A$27
Name ClubNames: NameLookup!$B$2:$B$402
Name ClubNumbers: NameLookup!$A$2:$A$402
Name MemberData: Event_01!$H$2
Name NonTenEvents: Calendar!$J$2:$J$27
Name Number2Name: NameLookup!$A$2:$B$402
Name RoundRobinNameToClub: RoundRobinRiders!$A$4:$C$33
Name RoundRobinNameToClubRange: RoundRobinRiders!$A$4:$C$229
Name RoundRobinRiderClubs: RoundRobinRiders!$B:$B
Name RoundRobinRiderDecoratedNames: RoundRobinRiders!$C:$C
Name RoundRobinRiderNames: RoundRobinRiders!$A:$A
Name TenMileEvents: Calendar!$K$2:$K$27

Sheet Revisions
A1: 42404 | B1: Mike Ives | C1: Prepared for 2016 season
A2: 45949 | B2: Mike Ives | C2: Created this from the old fully-functional "25 club championship.xlsm"
C3: Removed league and championship sheets - retained just the event sheets
C4: Remove calculated columns from the event sheets
C5: Retains calendar sheet, though I expect this will change
C6: WVCCData sheet is present but needs to be replace by the data from competitors_2025.csv as generated by the private github pipeline from membership .XLSX
A7: 45954 | B7: Mike Ives | C7: Some work on Calendar. Sheets renamed to Event_nn and Hill Climb (seconds have fractions) moved to be Event_01. New column in Calendar sheet indicates which Event_nn sheet is applicable. New isCancelled column added too.
A8: 46026 | B8: Mike Ives | C8: Updated with emailed sheet from Jon Durnin ("C:\Users\Mike\Dropbox\WVCC Results\Excel\2026\WVCC TT Events 2026 030126.xlsx").
C9: Updated formulas for calculating IsTen or not to look to see if there's a formula used. Hence =5+5 is seen as a non standard-ten
A10: 46046 | B10: Mike Ives | C10: Changed event sheets to use a formula in column A. Enter the actual name in column J instead and the formula will get the Club Number for members, or add the Club Name for Round Robin Riders
C11: =IF(J2="","",XLOOKUP(J2,ClubNames,ClubNumbers,XLOOKUP(J2,RoundRobinRiderNames,RoundRobinRiderDecoratedNames,J2)))
C12: If a RR rider from another club enters events *before* they join that other club, then simply overwrite the formula in column A for that rider - use the name string wanted in the results html.

Sheet Competitors
A1: ClubNumber | B1: Surname | C1: GivenName | D1: ClaimStatus | E1: isFemale | F1: AgeGroup | G1: VetsBucket | H1: ImportDate
A2: 1327 | B2: Abbott | C2: James | D2: First Claim | E2: FALSE | F2: Senior | H2: 46236
A3: 1237 | B3: Abbott | C3: John | D3: First Claim | E3: FALSE | F3: Veteran | G3: 1 | H3: 46236
A4: 819 | B4: Akoslovski | C4: Kath | D4: First Claim | E4: TRUE | F4: Veteran | G4: 23 | H4: 46236
A5: 2 | B5: Alden | C5: Steve | D5: First Claim | E5: FALSE | F5: Veteran | G5: 21 | H5: 46236
A6: 1370 | B6: Aldridge | C6: Ian | D6: First Claim | E6: FALSE | F6: Veteran | G6: 4 | H6: 46236
A7: 1415 | B7: Aldridge | C7: James | D7: First Claim | E7: FALSE | F7: Juvenile | H7: 46236
A8: 1286 | B8: Allen | C8: Ian | D8: First Claim | E8: FALSE | F8: Veteran | G8: 13 | H8: 46236
A9: 1381 | B9: Allen | C9: Roland | D9: First Claim | E9: FALSE | F9: Senior | H9: 46236
A10: 1112 | B10: Ashwell | C10: Gary | D10: First Claim | E10: FALSE | F10: Veteran | G10: 16 | H10: 46236
A11: 1135 | B11: Askham | C11: Simon | D11: First Claim | E11: FALSE | F11: Veteran | G11: 1 | H11: 46236
A12: 1430 | B12: Bacon | C12: Gary | D12: First Claim | E12: FALSE | F12: Veteran | G12: 4 | H12: 46236
A13: 982 | B13: Bacon | C13: Steve | D13: First Claim | E13: FALSE | F13: Veteran | G13: 22 | H13: 46236
A14: 1328 | B14: Bailey | C14: Shaun | D14: First Claim | E14: FALSE | F14: Veteran | G14: 4 | H14: 46236
A15: 369 | B15: Barnett | C15: Dean | D15: First Claim | E15: FALSE | F15: Veteran | G15: 8 | H15: 46236
A16: 7 | B16: Barnett | C16: Vic | D16: Honorary | E16: FALSE | F16: Veteran | G16: 32 | H16: 46236
A17: 473 | B17: Barnett | C17: George | D17: Honorary | E17: FALSE | F17: Veteran | G17: 33 | H17: 46236
A18: 1384 | B18: Barrett | C18: Paul | D18: First Claim | E18: FALSE | F18: Veteran | G18: 30 | H18: 46236
A19: 1348 | B19: Baxter | C19: Lydia | D19: Second Claim | E19: TRUE | F19: Senior | H19: 46236
A20: 1275 | B20: Baxter | C20: Sylvia | D20: First Claim | E20: TRUE | F20: Juvenile | H20: 46236
A21: 68 | B21: Beach | C21: Ronald | D21: Honorary | E21: FALSE | F21: Veteran | G21: 35 | H21: 46236
A22: 1035 | B22: Bell | C22: Peter | D22: First Claim | E22: FALSE | F22: Veteran | G22: 6 | H22: 46236
A23: 1416 | B23: Bellamy | C23: Henry | D23: First Claim | E23: FALSE | F23: Senior | H23: 46236
A24: 1326 | B24: Bennis | C24: Laoise | D24: First Claim | E24: TRUE | F24: Senior | H24: 46236
A25: 1431 | B25: Bewick | C25: Angela | D25: First Claim | E25: TRUE | F25: Veteran | G25: 11 | H25: 46236
A26: 477 | B26: Birch | C26: Carol | D26: First Claim | E26: TRUE | F26: Veteran | G26: 34 | H26: 46236
A27: 10 | B27: Birch | C27: Dave | D27: Honorary | E27: FALSE | F27: Veteran | G27: 35 | H27: 46236
A28: 1414 | B28: Boney | C28: Allen | D28: First Claim | E28: FALSE | F28: Veteran | G28: 13 | H28: 46236
A29: 1029 | B29: Bowie | C29: Victor | D29: First Claim | E29: FALSE | F29: Veteran | G29: 28 | H29: 46236
A30: 13 | B30: Bramford | C30: Paul | D30: First Claim | E30: FALSE | F30: Veteran | G30: 28 | H30: 46236
A31: 1255 | B31: Bridgstock | C31: Anne | D31: First Claim | E31: TRUE | F31: Veteran | G31: 13 | H31: 46236
A32: 1405 | B32: Brinkman | C32: Elise | D32: First Claim | E32: TRUE | F32: Juvenile | H32: 46236
A33: 1421 | B33: Brown | C33: Gill | D33: First Claim | E33: TRUE | F33: Veteran | G33: 12 | H33: 46236
A34: 1418 | B34: Brown | C34: James | D34: First Claim | E34: FALSE | F34: Senior | H34: 46236
A35: 919 | B35: Brundell | C35: Paul | D35: First Claim | E35: FALSE | F35: Veteran | G35: 16 | H35: 46236
A36: 1436 | B36: Burbery | C36: Shaun | D36: First Claim | E36: FALSE | F36: Veteran | G36: 14 | H36: 46236
A37: 1319 | B37: Burgess | C37: Steve | D37: First Claim | E37: FALSE | F37: Veteran | G37: 9 | H37: 46236
A38: 1190 | B38: Burke | C38: Jacob | D38: First Claim | E38: FALSE | F38: Juvenile | H38: 46236
A39: 1189 | B39: Burke | C39: Max | D39: First Claim | E39: FALSE | F39: Juvenile | H39: 46236
A40: 735 | B40: Burke | C40: Michael | D40: Second Claim | E40: FALSE | F40: Senior | H40: 46236
...

Sheet 0307_competitors_2026
A1: ClubNumber | B1: Surname | C1: GivenName | D1: ClaimStatus | E1: isFemale | F1: AgeGroup | G1: VetsBucket | H1: ImportDate
A2: 1327 | B2: Abbott | C2: James | D2: First Claim | E2: FALSE | F2: Senior | H2: 46088
A3: 1237 | B3: Abbott | C3: John | D3: First Claim | E3: FALSE | F3: Veteran | G3: 1 | H3: 46088
A4: 819 | B4: Akoslovski | C4: Kath | D4: First Claim | E4: TRUE | F4: Veteran | G4: 23 | H4: 46088
A5: 2 | B5: Alden | C5: Steve | D5: First Claim | E5: FALSE | F5: Veteran | G5: 21 | H5: 46088
A6: 1370 | B6: Aldridge | C6: Ian | D6: First Claim | E6: FALSE | F6: Veteran | G6: 4 | H6: 46088
A7: 1415 | B7: Aldridge | C7: James | D7: First Claim | E7: FALSE | F7: Juvenile | H7: 46088
A8: 1286 | B8: Allen | C8: Ian | D8: First Claim | E8: FALSE | F8: Veteran | G8: 13 | H8: 46088
A9: 1381 | B9: Allen | C9: Roland | D9: First Claim | E9: FALSE | F9: Senior | H9: 46088
A10: 1135 | B10: Askham | C10: Simon | D10: First Claim | E10: FALSE | F10: Veteran | G10: 1 | H10: 46088
A11: 982 | B11: Bacon | C11: Steve | D11: First Claim | E11: FALSE | F11: Veteran | G11: 22 | H11: 46088
A12: 1328 | B12: Bailey | C12: Shaun | D12: First Claim | E12: FALSE | F12: Veteran | G12: 4 | H12: 46088
A13: 369 | B13: Barnett | C13: Dean | D13: First Claim | E13: FALSE | F13: Veteran | G13: 8 | H13: 46088
A14: 7 | B14: Barnett | C14: Vic | D14: Honorary | E14: FALSE | F14: Veteran | G14: 32 | H14: 46088
A15: 473 | B15: Barnett | C15: George | D15: Honorary | E15: FALSE | F15: Veteran | G15: 33 | H15: 46088
A16: 1384 | B16: Barrett | C16: Paul | D16: First Claim | E16: FALSE | F16: Veteran | G16: 30 | H16: 46088
A17: 1348 | B17: Baxter | C17: Lydia | D17: Second Claim | E17: TRUE | F17: Senior | H17: 46088
A18: 1275 | B18: Baxter | C18: Sylvia | D18: First Claim | E18: TRUE | F18: Juvenile | H18: 46088
A19: 68 | B19: Beach | C19: Ronald | D19: Honorary | E19: FALSE | F19: Veteran | G19: 35 | H19: 46088
A20: 1035 | B20: Bell | C20: Peter | D20: First Claim | E20: FALSE | F20: Veteran | G20: 6 | H20: 46088
A21: 1326 | B21: Bennis | C21: Laoise | D21: First Claim | E21: TRUE | F21: Senior | H21: 46088
A22: 477 | B22: Birch | C22: Carol | D22: First Claim | E22: TRUE | F22: Veteran | G22: 34 | H22: 46088
A23: 10 | B23: Birch | C23: Dave | D23: Honorary | E23: FALSE | F23: Veteran | G23: 35 | H23: 46088
A24: 1414 | B24: Boney | C24: Allen | D24: First Claim | E24: FALSE | F24: Veteran | G24: 13 | H24: 46088
A25: 1029 | B25: Bowie | C25: Victor | D25: First Claim | E25: FALSE | F25: Veteran | G25: 28 | H25: 46088
A26: 13 | B26: Bramford | C26: Paul | D26: First Claim | E26: FALSE | F26: Veteran | G26: 28 | H26: 46088
A27: 1255 | B27: Bridgstock | C27: Anne | D27: First Claim | E27: TRUE | F27: Veteran | G27: 13 | H27: 46088
A28: 1405 | B28: Brinkman | C28: Elise | D28: First Claim | E28: TRUE | F28: Juvenile | H28: 46088
A29: 919 | B29: Brundell | C29: Paul | D29: First Claim | E29: FALSE | F29: Veteran | G29: 16 | H29: 46088
A30: 1319 | B30: Burgess | C30: Steve | D30: First Claim | E30: FALSE | F30: Veteran | G30: 9 | H30: 46088
A31: 1389 | B31: Campbell | C31: Billy | D31: First Claim | E31: FALSE | F31: Senior | H31: 46088
A32: 482 | B32: Clarke | C32: Nick | D32: First Claim | E32: FALSE | F32: Veteran | G32: 13 | H32: 46088
A33: 674 | B33: Clegg | C33: Jennifer | D33: Second Claim | E33: TRUE | F33: Veteran | G33: 23 | H33: 46088
A34: 1061 | B34: Collis | C34: Daryl | D34: First Claim | E34: FALSE | F34: Veteran | G34: 19 | H34: 46088
A35: 763 | B35: Condon | C35: Peter | D35: First Claim | E35: FALSE | F35: Veteran | G35: 17 | H35: 46088
A36: 1227 | B36: Copson | C36: Yvonne | D36: First Claim | E36: TRUE | F36: Veteran | G36: 8 | H36: 46088
A37: 715 | B37: Coulam | C37: Steven | D37: First Claim | E37: FALSE | F37: Veteran | G37: 5 | H37: 46088
A38: 567 | B38: Cox | C38: Lawrence | D38: First Claim | E38: FALSE | F38: Veteran | G38: 7 | H38: 46088
A39: 1391 | B39: Cuthbertson | C39: Leah | D39: First Claim | E39: TRUE | F39: Senior | H39: 46088
A40: 704 | B40: Dainty | C40: Chris | D40: First Claim | E40: FALSE | F40: Veteran | G40: 21 | H40: 46088
...

Sheet 0310_competitors_2026
A1: ClubNumber | B1: Surname | C1: GivenName | D1: ClaimStatus | E1: isFemale | F1: AgeGroup | G1: VetsBucket | H1: ImportDate
A2: 1327 | B2: Abbott | C2: James | D2: First Claim | E2: FALSE | F2: Senior | H2: 46091
A3: 1237 | B3: Abbott | C3: John | D3: First Claim | E3: FALSE | F3: Veteran | G3: 1 | H3: 46091
A4: 819 | B4: Akoslovski | C4: Kath | D4: First Claim | E4: TRUE | F4: Veteran | G4: 23 | H4: 46091
A5: 2 | B5: Alden | C5: Steve | D5: First Claim | E5: FALSE | F5: Veteran | G5: 21 | H5: 46091
A6: 1370 | B6: Aldridge | C6: Ian | D6: First Claim | E6: FALSE | F6: Veteran | G6: 4 | H6: 46091
A7: 1415 | B7: Aldridge | C7: James | D7: First Claim | E7: FALSE | F7: Juvenile | H7: 46091
A8: 1286 | B8: Allen | C8: Ian | D8: First Claim | E8: FALSE | F8: Veteran | G8: 13 | H8: 46091
A9: 1381 | B9: Allen | C9: Roland | D9: First Claim | E9: FALSE | F9: Senior | H9: 46091
A10: 1112 | B10: Ashwell | C10: Gary | D10: First Claim | E10: FALSE | F10: Veteran | G10: 16 | H10: 46091
A11: 1135 | B11: Askham | C11: Simon | D11: First Claim | E11: FALSE | F11: Veteran | G11: 1 | H11: 46091
A12: 982 | B12: Bacon | C12: Steve | D12: First Claim | E12: FALSE | F12: Veteran | G12: 22 | H12: 46091
A13: 1328 | B13: Bailey | C13: Shaun | D13: First Claim | E13: FALSE | F13: Veteran | G13: 4 | H13: 46091
A14: 369 | B14: Barnett | C14: Dean | D14: First Claim | E14: FALSE | F14: Veteran | G14: 8 | H14: 46091
A15: 7 | B15: Barnett | C15: Vic | D15: Honorary | E15: FALSE | F15: Veteran | G15: 32 | H15: 46091
A16: 473 | B16: Barnett | C16: George | D16: Honorary | E16: FALSE | F16: Veteran | G16: 33 | H16: 46091
A17: 1384 | B17: Barrett | C17: Paul | D17: First Claim | E17: FALSE | F17: Veteran | G17: 30 | H17: 46091
A18: 1348 | B18: Baxter | C18: Lydia | D18: Second Claim | E18: TRUE | F18: Senior | H18: 46091
A19: 1275 | B19: Baxter | C19: Sylvia | D19: First Claim | E19: TRUE | F19: Juvenile | H19: 46091
A20: 68 | B20: Beach | C20: Ronald | D20: Honorary | E20: FALSE | F20: Veteran | G20: 35 | H20: 46091
A21: 1035 | B21: Bell | C21: Peter | D21: First Claim | E21: FALSE | F21: Veteran | G21: 6 | H21: 46091
A22: 1416 | B22: Bellamy | C22: Henry | D22: First Claim | E22: FALSE | F22: Senior | H22: 46091
A23: 1326 | B23: Bennis | C23: Laoise | D23: First Claim | E23: TRUE | F23: Senior | H23: 46091
A24: 477 | B24: Birch | C24: Carol | D24: First Claim | E24: TRUE | F24: Veteran | G24: 34 | H24: 46091
A25: 10 | B25: Birch | C25: Dave | D25: Honorary | E25: FALSE | F25: Veteran | G25: 35 | H25: 46091
A26: 1414 | B26: Boney | C26: Allen | D26: First Claim | E26: FALSE | F26: Veteran | G26: 13 | H26: 46091
A27: 1029 | B27: Bowie | C27: Victor | D27: First Claim | E27: FALSE | F27: Veteran | G27: 28 | H27: 46091
A28: 13 | B28: Bramford | C28: Paul | D28: First Claim | E28: FALSE | F28: Veteran | G28: 28 | H28: 46091
A29: 1255 | B29: Bridgstock | C29: Anne | D29: First Claim | E29: TRUE | F29: Veteran | G29: 13 | H29: 46091
A30: 1405 | B30: Brinkman | C30: Elise | D30: First Claim | E30: TRUE | F30: Juvenile | H30: 46091
A31: 919 | B31: Brundell | C31: Paul | D31: First Claim | E31: FALSE | F31: Veteran | G31: 16 | H31: 46091
A32: 1319 | B32: Burgess | C32: Steve | D32: First Claim | E32: FALSE | F32: Veteran | G32: 9 | H32: 46091
A33: 1389 | B33: Campbell | C33: Billy | D33: First Claim | E33: FALSE | F33: Senior | H33: 46091
A34: 482 | B34: Clarke | C34: Nick | D34: First Claim | E34: FALSE | F34: Veteran | G34: 13 | H34: 46091
A35: 674 | B35: Clegg | C35: Jennifer | D35: Second Claim | E35: TRUE | F35: Veteran | G35: 23 | H35: 46091
A36: 1061 | B36: Collis | C36: Daryl | D36: First Claim | E36: FALSE | F36: Veteran | G36: 19 | H36: 46091
A37: 763 | B37: Condon | C37: Peter | D37: First Claim | E37: FALSE | F37: Veteran | G37: 17 | H37: 46091
A38: 1227 | B38: Copson | C38: Yvonne | D38: First Claim | E38: TRUE | F38: Veteran | G38: 8 | H38: 46091
A39: 715 | B39: Coulam | C39: Steven | D39: First Claim | E39: FALSE | F39: Veteran | G39: 5 | H39: 46091
A40: 567 | B40: Cox | C40: Lawrence | D40: First Claim | E40: FALSE | F40: Veteran | G40: 7 | H40: 46091
...

Sheet 0321_competitors_2026
A1: ClubNumber | B1: Surname | C1: GivenName | D1: ClaimStatus | E1: isFemale | F1: AgeGroup | G1: VetsBucket | H1: ImportDate
A2: 1327 | B2: Abbott | C2: James | D2: First Claim | E2: FALSE | F2: Senior | H2: 46102
A3: 1237 | B3: Abbott | C3: John | D3: First Claim | E3: FALSE | F3: Veteran | G3: 1 | H3: 46102
A4: 819 | B4: Akoslovski | C4: Kath | D4: First Claim | E4: TRUE | F4: Veteran | G4: 23 | H4: 46102
A5: 2 | B5: Alden | C5: Steve | D5: First Claim | E5: FALSE | F5: Veteran | G5: 21 | H5: 46102
A6: 1370 | B6: Aldridge | C6: Ian | D6: First Claim | E6: FALSE | F6: Veteran | G6: 4 | H6: 46102
A7: 1415 | B7: Aldridge | C7: James | D7: First Claim | E7: FALSE | F7: Juvenile | H7: 46102
A8: 1286 | B8: Allen | C8: Ian | D8: First Claim | E8: FALSE | F8: Veteran | G8: 13 | H8: 46102
A9: 1381 | B9: Allen | C9: Roland | D9: First Claim | E9: FALSE | F9: Senior | H9: 46102
A10: 1112 | B10: Ashwell | C10: Gary | D10: First Claim | E10: FALSE | F10: Veteran | G10: 16 | H10: 46102
A11: 1135 | B11: Askham | C11: Simon | D11: First Claim | E11: FALSE | F11: Veteran | G11: 1 | H11: 46102
A12: 982 | B12: Bacon | C12: Steve | D12: First Claim | E12: FALSE | F12: Veteran | G12: 22 | H12: 46102
A13: 1328 | B13: Bailey | C13: Shaun | D13: First Claim | E13: FALSE | F13: Veteran | G13: 4 | H13: 46102
A14: 369 | B14: Barnett | C14: Dean | D14: First Claim | E14: FALSE | F14: Veteran | G14: 8 | H14: 46102
A15: 7 | B15: Barnett | C15: Vic | D15: Honorary | E15: FALSE | F15: Veteran | G15: 32 | H15: 46102
A16: 473 | B16: Barnett | C16: George | D16: Honorary | E16: FALSE | F16: Veteran | G16: 33 | H16: 46102
A17: 1384 | B17: Barrett | C17: Paul | D17: First Claim | E17: FALSE | F17: Veteran | G17: 30 | H17: 46102
A18: 1348 | B18: Baxter | C18: Lydia | D18: Second Claim | E18: TRUE | F18: Senior | H18: 46102
A19: 1275 | B19: Baxter | C19: Sylvia | D19: First Claim | E19: TRUE | F19: Juvenile | H19: 46102
A20: 68 | B20: Beach | C20: Ronald | D20: Honorary | E20: FALSE | F20: Veteran | G20: 35 | H20: 46102
A21: 1035 | B21: Bell | C21: Peter | D21: First Claim | E21: FALSE | F21: Veteran | G21: 6 | H21: 46102
A22: 1416 | B22: Bellamy | C22: Henry | D22: First Claim | E22: FALSE | F22: Senior | H22: 46102
A23: 1326 | B23: Bennis | C23: Laoise | D23: First Claim | E23: TRUE | F23: Senior | H23: 46102
A24: 477 | B24: Birch | C24: Carol | D24: First Claim | E24: TRUE | F24: Veteran | G24: 34 | H24: 46102
A25: 10 | B25: Birch | C25: Dave | D25: Honorary | E25: FALSE | F25: Veteran | G25: 35 | H25: 46102
A26: 1414 | B26: Boney | C26: Allen | D26: First Claim | E26: FALSE | F26: Veteran | G26: 13 | H26: 46102
A27: 1029 | B27: Bowie | C27: Victor | D27: First Claim | E27: FALSE | F27: Veteran | G27: 28 | H27: 46102
A28: 13 | B28: Bramford | C28: Paul | D28: First Claim | E28: FALSE | F28: Veteran | G28: 28 | H28: 46102
A29: 1255 | B29: Bridgstock | C29: Anne | D29: First Claim | E29: TRUE | F29: Veteran | G29: 13 | H29: 46102
A30: 1405 | B30: Brinkman | C30: Elise | D30: First Claim | E30: TRUE | F30: Juvenile | H30: 46102
A31: 1418 | B31: Brown | C31: James | D31: First Claim | E31: FALSE | F31: Senior | H31: 46102
A32: 919 | B32: Brundell | C32: Paul | D32: First Claim | E32: FALSE | F32: Veteran | G32: 16 | H32: 46102
A33: 1319 | B33: Burgess | C33: Steve | D33: First Claim | E33: FALSE | F33: Veteran | G33: 9 | H33: 46102
A34: 1389 | B34: Campbell | C34: Billy | D34: First Claim | E34: FALSE | F34: Senior | H34: 46102
A35: 940 | B35: Chapman | C35: Alison | D35: First Claim | E35: TRUE | F35: Veteran | G35: 9 | H35: 46102
A36: 806 | B36: Chapman | C36: Mark | D36: First Claim | E36: FALSE | F36: Veteran | G36: 11 | H36: 46102
A37: 482 | B37: Clarke | C37: Nick | D37: First Claim | E37: FALSE | F37: Veteran | G37: 13 | H37: 46102
A38: 674 | B38: Clegg | C38: Jennifer | D38: Second Claim | E38: TRUE | F38: Veteran | G38: 23 | H38: 46102
A39: 1061 | B39: Collis | C39: Daryl | D39: First Claim | E39: FALSE | F39: Veteran | G39: 19 | H39: 46102
A40: 763 | B40: Condon | C40: Peter | D40: First Claim | E40: FALSE | F40: Veteran | G40: 17 | H40: 46102
...

Sheet 0407_competitors_2026
A1: ClubNumber | B1: Surname | C1: GivenName | D1: ClaimStatus | E1: isFemale | F1: AgeGroup | G1: VetsBucket | H1: ImportDate
A2: 1327 | B2: Abbott | C2: James | D2: First Claim | E2: FALSE | F2: Senior | H2: 46119
A3: 1237 | B3: Abbott | C3: John | D3: First Claim | E3: FALSE | F3: Veteran | G3: 1 | H3: 46119
A4: 819 | B4: Akoslovski | C4: Kath | D4: First Claim | E4: TRUE | F4: Veteran | G4: 23 | H4: 46119
A5: 2 | B5: Alden | C5: Steve | D5: First Claim | E5: FALSE | F5: Veteran | G5: 21 | H5: 46119
A6: 1370 | B6: Aldridge | C6: Ian | D6: First Claim | E6: FALSE | F6: Veteran | G6: 4 | H6: 46119
A7: 1415 | B7: Aldridge | C7: James | D7: First Claim | E7: FALSE | F7: Juvenile | H7: 46119
A8: 1286 | B8: Allen | C8: Ian | D8: First Claim | E8: FALSE | F8: Veteran | G8: 13 | H8: 46119
A9: 1381 | B9: Allen | C9: Roland | D9: First Claim | E9: FALSE | F9: Senior | H9: 46119
A10: 1112 | B10: Ashwell | C10: Gary | D10: First Claim | E10: FALSE | F10: Veteran | G10: 16 | H10: 46119
A11: 1135 | B11: Askham | C11: Simon | D11: First Claim | E11: FALSE | F11: Veteran | G11: 1 | H11: 46119
A12: 982 | B12: Bacon | C12: Steve | D12: First Claim | E12: FALSE | F12: Veteran | G12: 22 | H12: 46119
A13: 1328 | B13: Bailey | C13: Shaun | D13: First Claim | E13: FALSE | F13: Veteran | G13: 4 | H13: 46119
A14: 369 | B14: Barnett | C14: Dean | D14: First Claim | E14: FALSE | F14: Veteran | G14: 8 | H14: 46119
A15: 7 | B15: Barnett | C15: Vic | D15: Honorary | E15: FALSE | F15: Veteran | G15: 32 | H15: 46119
A16: 473 | B16: Barnett | C16: George | D16: Honorary | E16: FALSE | F16: Veteran | G16: 33 | H16: 46119
A17: 1384 | B17: Barrett | C17: Paul | D17: First Claim | E17: FALSE | F17: Veteran | G17: 30 | H17: 46119
A18: 1348 | B18: Baxter | C18: Lydia | D18: Second Claim | E18: TRUE | F18: Senior | H18: 46119
A19: 1275 | B19: Baxter | C19: Sylvia | D19: First Claim | E19: TRUE | F19: Juvenile | H19: 46119
A20: 68 | B20: Beach | C20: Ronald | D20: Honorary | E20: FALSE | F20: Veteran | G20: 35 | H20: 46119
A21: 1035 | B21: Bell | C21: Peter | D21: First Claim | E21: FALSE | F21: Veteran | G21: 6 | H21: 46119
A22: 1416 | B22: Bellamy | C22: Henry | D22: First Claim | E22: FALSE | F22: Senior | H22: 46119
A23: 1326 | B23: Bennis | C23: Laoise | D23: First Claim | E23: TRUE | F23: Senior | H23: 46119
A24: 477 | B24: Birch | C24: Carol | D24: First Claim | E24: TRUE | F24: Veteran | G24: 34 | H24: 46119
A25: 10 | B25: Birch | C25: Dave | D25: Honorary | E25: FALSE | F25: Veteran | G25: 35 | H25: 46119
A26: 1414 | B26: Boney | C26: Allen | D26: First Claim | E26: FALSE | F26: Veteran | G26: 13 | H26: 46119
A27: 1029 | B27: Bowie | C27: Victor | D27: First Claim | E27: FALSE | F27: Veteran | G27: 28 | H27: 46119
A28: 13 | B28: Bramford | C28: Paul | D28: First Claim | E28: FALSE | F28: Veteran | G28: 28 | H28: 46119
A29: 1255 | B29: Bridgstock | C29: Anne | D29: First Claim | E29: TRUE | F29: Veteran | G29: 13 | H29: 46119
A30: 1405 | B30: Brinkman | C30: Elise | D30: First Claim | E30: TRUE | F30: Juvenile | H30: 46119
A31: 1418 | B31: Brown | C31: James | D31: First Claim | E31: FALSE | F31: Senior | H31: 46119
A32: 919 | B32: Brundell | C32: Paul | D32: First Claim | E32: FALSE | F32: Veteran | G32: 16 | H32: 46119
A33: 1319 | B33: Burgess | C33: Steve | D33: First Claim | E33: FALSE | F33: Veteran | G33: 9 | H33: 46119
A34: 1389 | B34: Campbell | C34: Billy | D34: First Claim | E34: FALSE | F34: Senior | H34: 46119
A35: 940 | B35: Chapman | C35: Alison | D35: First Claim | E35: TRUE | F35: Veteran | G35: 9 | H35: 46119
A36: 806 | B36: Chapman | C36: Mark | D36: First Claim | E36: FALSE | F36: Veteran | G36: 11 | H36: 46119
A37: 482 | B37: Clarke | C37: Nick | D37: First Claim | E37: FALSE | F37: Veteran | G37: 13 | H37: 46119
A38: 674 | B38: Clegg | C38: Jennifer | D38: Second Claim | E38: TRUE | F38: Veteran | G38: 23 | H38: 46119
A39: 1061 | B39: Collis | C39: Daryl | D39: First Claim | E39: FALSE | F39: Veteran | G39: 19 | H39: 46119
A40: 763 | B40: Condon | C40: Peter | D40: First Claim | E40: FALSE | F40: Veteran | G40: 17 | H40: 46119
...

Sheet 0407_competitors_2026b
A1: ClubNumber | B1: Surname | C1: GivenName | D1: ClaimStatus | E1: isFemale | F1: AgeGroup | G1: VetsBucket | H1: ImportDate
A2: 1327 | B2: Abbott | C2: James | D2: First Claim | E2: FALSE | F2: Senior | H2: 46119
A3: 1237 | B3: Abbott | C3: John | D3: First Claim | E3: FALSE | F3: Veteran | G3: 1 | H3: 46119
A4: 819 | B4: Akoslovski | C4: Kath | D4: First Claim | E4: TRUE | F4: Veteran | G4: 23 | H4: 46119
A5: 2 | B5: Alden | C5: Steve | D5: First Claim | E5: FALSE | F5: Veteran | G5: 21 | H5: 46119
A6: 1370 | B6: Aldridge | C6: Ian | D6: First Claim | E6: FALSE | F6: Veteran | G6: 4 | H6: 46119
A7: 1415 | B7: Aldridge | C7: James | D7: First Claim | E7: FALSE | F7: Juvenile | H7: 46119
A8: 1286 | B8: Allen | C8: Ian | D8: First Claim | E8: FALSE | F8: Veteran | G8: 13 | H8: 46119
A9: 1381 | B9: Allen | C9: Roland | D9: First Claim | E9: FALSE | F9: Senior | H9: 46119
A10: 1112 | B10: Ashwell | C10: Gary | D10: First Claim | E10: FALSE | F10: Veteran | G10: 16 | H10: 46119
A11: 1135 | B11: Askham | C11: Simon | D11: First Claim | E11: FALSE | F11: Veteran | G11: 1 | H11: 46119
A12: 982 | B12: Bacon | C12: Steve | D12: First Claim | E12: FALSE | F12: Veteran | G12: 22 | H12: 46119
A13: 1328 | B13: Bailey | C13: Shaun | D13: First Claim | E13: FALSE | F13: Veteran | G13: 4 | H13: 46119
A14: 369 | B14: Barnett | C14: Dean | D14: First Claim | E14: FALSE | F14: Veteran | G14: 8 | H14: 46119
A15: 7 | B15: Barnett | C15: Vic | D15: Honorary | E15: FALSE | F15: Veteran | G15: 32 | H15: 46119
A16: 473 | B16: Barnett | C16: George | D16: Honorary | E16: FALSE | F16: Veteran | G16: 33 | H16: 46119
A17: 1384 | B17: Barrett | C17: Paul | D17: First Claim | E17: FALSE | F17: Veteran | G17: 30 | H17: 46119
A18: 1348 | B18: Baxter | C18: Lydia | D18: Second Claim | E18: TRUE | F18: Senior | H18: 46119
A19: 1275 | B19: Baxter | C19: Sylvia | D19: First Claim | E19: TRUE | F19: Juvenile | H19: 46119
A20: 68 | B20: Beach | C20: Ronald | D20: Honorary | E20: FALSE | F20: Veteran | G20: 35 | H20: 46119
A21: 1035 | B21: Bell | C21: Peter | D21: First Claim | E21: FALSE | F21: Veteran | G21: 6 | H21: 46119
A22: 1416 | B22: Bellamy | C22: Henry | D22: First Claim | E22: FALSE | F22: Senior | H22: 46119
A23: 1326 | B23: Bennis | C23: Laoise | D23: First Claim | E23: TRUE | F23: Senior | H23: 46119
A24: 477 | B24: Birch | C24: Carol | D24: First Claim | E24: TRUE | F24: Veteran | G24: 34 | H24: 46119
A25: 10 | B25: Birch | C25: Dave | D25: Honorary | E25: FALSE | F25: Veteran | G25: 35 | H25: 46119
A26: 1414 | B26: Boney | C26: Allen | D26: First Claim | E26: FALSE | F26: Veteran | G26: 13 | H26: 46119
A27: 1029 | B27: Bowie | C27: Victor | D27: First Claim | E27: FALSE | F27: Veteran | G27: 28 | H27: 46119
A28: 13 | B28: Bramford | C28: Paul | D28: First Claim | E28: FALSE | F28: Veteran | G28: 28 | H28: 46119
A29: 1255 | B29: Bridgstock | C29: Anne | D29: First Claim | E29: TRUE | F29: Veteran | G29: 13 | H29: 46119
A30: 1405 | B30: Brinkman | C30: Elise | D30: First Claim | E30: TRUE | F30: Juvenile | H30: 46119
A31: 1418 | B31: Brown | C31: James | D31: First Claim | E31: FALSE | F31: Senior | H31: 46119
A32: 919 | B32: Brundell | C32: Paul | D32: First Claim | E32: FALSE | F32: Veteran | G32: 16 | H32: 46119
A33: 1319 | B33: Burgess | C33: Steve | D33: First Claim | E33: FALSE | F33: Veteran | G33: 9 | H33: 46119
A34: 1389 | B34: Campbell | C34: Billy | D34: First Claim | E34: FALSE | F34: Senior | H34: 46119
A35: 940 | B35: Chapman | C35: Alison | D35: First Claim | E35: TRUE | F35: Veteran | G35: 9 | H35: 46119
A36: 806 | B36: Chapman | C36: Mark | D36: First Claim | E36: FALSE | F36: Veteran | G36: 11 | H36: 46119
A37: 482 | B37: Clarke | C37: Nick | D37: First Claim | E37: FALSE | F37: Veteran | G37: 13 | H37: 46119
A38: 674 | B38: Clegg | C38: Jennifer | D38: Second Claim | E38: TRUE | F38: Veteran | G38: 23 | H38: 46119
A39: 1061 | B39: Collis | C39: Daryl | D39: First Claim | E39: FALSE | F39: Veteran | G39: 19 | H39: 46119
A40: 763 | B40: Condon | C40: Peter | D40: First Claim | E40: FALSE | F40: Veteran | G40: 17 | H40: 46119
...

Sheet 0409_competitors_2026
A1: ClubNumber | B1: Surname | C1: GivenName | D1: ClaimStatus | E1: isFemale | F1: AgeGroup | G1: VetsBucket | H1: ImportDate
A2: 1327 | B2: Abbott | C2: James | D2: First Claim | E2: FALSE | F2: Senior | H2: 46121
A3: 1237 | B3: Abbott | C3: John | D3: First Claim | E3: FALSE | F3: Veteran | G3: 1 | H3: 46121
A4: 819 | B4: Akoslovski | C4: Kath | D4: First Claim | E4: TRUE | F4: Veteran | G4: 23 | H4: 46121
A5: 2 | B5: Alden | C5: Steve | D5: First Claim | E5: FALSE | F5: Veteran | G5: 21 | H5: 46121
A6: 1370 | B6: Aldridge | C6: Ian | D6: First Claim | E6: FALSE | F6: Veteran | G6: 4 | H6: 46121
A7: 1415 | B7: Aldridge | C7: James | D7: First Claim | E7: FALSE | F7: Juvenile | H7: 46121
A8: 1286 | B8: Allen | C8: Ian | D8: First Claim | E8: FALSE | F8: Veteran | G8: 13 | H8: 46121
A9: 1381 | B9: Allen | C9: Roland | D9: First Claim | E9: FALSE | F9: Senior | H9: 46121
A10: 1112 | B10: Ashwell | C10: Gary | D10: First Claim | E10: FALSE | F10: Veteran | G10: 16 | H10: 46121
A11: 1135 | B11: Askham | C11: Simon | D11: First Claim | E11: FALSE | F11: Veteran | G11: 1 | H11: 46121
A12: 982 | B12: Bacon | C12: Steve | D12: First Claim | E12: FALSE | F12: Veteran | G12: 22 | H12: 46121
A13: 1328 | B13: Bailey | C13: Shaun | D13: First Claim | E13: FALSE | F13: Veteran | G13: 4 | H13: 46121
A14: 369 | B14: Barnett | C14: Dean | D14: First Claim | E14: FALSE | F14: Veteran | G14: 8 | H14: 46121
A15: 7 | B15: Barnett | C15: Vic | D15: Honorary | E15: FALSE | F15: Veteran | G15: 32 | H15: 46121
A16: 473 | B16: Barnett | C16: George | D16: Honorary | E16: FALSE | F16: Veteran | G16: 33 | H16: 46121
A17: 1384 | B17: Barrett | C17: Paul | D17: First Claim | E17: FALSE | F17: Veteran | G17: 30 | H17: 46121
A18: 1348 | B18: Baxter | C18: Lydia | D18: Second Claim | E18: TRUE | F18: Senior | H18: 46121
A19: 1275 | B19: Baxter | C19: Sylvia | D19: First Claim | E19: TRUE | F19: Juvenile | H19: 46121
A20: 68 | B20: Beach | C20: Ronald | D20: Honorary | E20: FALSE | F20: Veteran | G20: 35 | H20: 46121
A21: 1035 | B21: Bell | C21: Peter | D21: First Claim | E21: FALSE | F21: Veteran | G21: 6 | H21: 46121
A22: 1416 | B22: Bellamy | C22: Henry | D22: First Claim | E22: FALSE | F22: Senior | H22: 46121
A23: 1326 | B23: Bennis | C23: Laoise | D23: First Claim | E23: TRUE | F23: Senior | H23: 46121
A24: 477 | B24: Birch | C24: Carol | D24: First Claim | E24: TRUE | F24: Veteran | G24: 34 | H24: 46121
A25: 10 | B25: Birch | C25: Dave | D25: Honorary | E25: FALSE | F25: Veteran | G25: 35 | H25: 46121
A26: 1414 | B26: Boney | C26: Allen | D26: First Claim | E26: FALSE | F26: Veteran | G26: 13 | H26: 46121
A27: 1029 | B27: Bowie | C27: Victor | D27: First Claim | E27: FALSE | F27: Veteran | G27: 28 | H27: 46121
A28: 13 | B28: Bramford | C28: Paul | D28: First Claim | E28: FALSE | F28: Veteran | G28: 28 | H28: 46121
A29: 1255 | B29: Bridgstock | C29: Anne | D29: First Claim | E29: TRUE | F29: Veteran | G29: 13 | H29: 46121
A30: 1405 | B30: Brinkman | C30: Elise | D30: First Claim | E30: TRUE | F30: Juvenile | H30: 46121
A31: 1421 | B31: Brown | C31: Gill | D31: First Claim | E31: TRUE | F31: Veteran | G31: 12 | H31: 46121
A32: 1418 | B32: Brown | C32: James | D32: First Claim | E32: FALSE | F32: Senior | H32: 46121
A33: 919 | B33: Brundell | C33: Paul | D33: First Claim | E33: FALSE | F33: Veteran | G33: 16 | H33: 46121
A34: 1319 | B34: Burgess | C34: Steve | D34: First Claim | E34: FALSE | F34: Veteran | G34: 9 | H34: 46121
A35: 1389 | B35: Campbell | C35: Billy | D35: First Claim | E35: FALSE | F35: Senior | H35: 46121
A36: 940 | B36: Chapman | C36: Alison | D36: First Claim | E36: TRUE | F36: Veteran | G36: 9 | H36: 46121
A37: 806 | B37: Chapman | C37: Mark | D37: First Claim | E37: FALSE | F37: Veteran | G37: 11 | H37: 46121
A38: 482 | B38: Clarke | C38: Nick | D38: First Claim | E38: FALSE | F38: Veteran | G38: 13 | H38: 46121
A39: 674 | B39: Clegg | C39: Jennifer | D39: Second Claim | E39: TRUE | F39: Veteran | G39: 23 | H39: 46121
A40: 1061 | B40: Collis | C40: Daryl | D40: First Claim | E40: FALSE | F40: Veteran | G40: 19 | H40: 46121
...

Sheet 0413_competitors_2026
A1: ClubNumber | B1: Surname | C1: GivenName | D1: ClaimStatus | E1: isFemale | F1: AgeGroup | G1: VetsBucket | H1: ImportDate
A2: 1327 | B2: Abbott | C2: James | D2: First Claim | E2: FALSE | F2: Senior | H2: 46125
A3: 1237 | B3: Abbott | C3: John | D3: First Claim | E3: FALSE | F3: Veteran | G3: 1 | H3: 46125
A4: 819 | B4: Akoslovski | C4: Kath | D4: First Claim | E4: TRUE | F4: Veteran | G4: 23 | H4: 46125
A5: 2 | B5: Alden | C5: Steve | D5: First Claim | E5: FALSE | F5: Veteran | G5: 21 | H5: 46125
A6: 1370 | B6: Aldridge | C6: Ian | D6: First Claim | E6: FALSE | F6: Veteran | G6: 4 | H6: 46125
A7: 1415 | B7: Aldridge | C7: James | D7: First Claim | E7: FALSE | F7: Juvenile | H7: 46125
A8: 1286 | B8: Allen | C8: Ian | D8: First Claim | E8: FALSE | F8: Veteran | G8: 13 | H8: 46125
A9: 1381 | B9: Allen | C9: Roland | D9: First Claim | E9: FALSE | F9: Senior | H9: 46125
A10: 1112 | B10: Ashwell | C10: Gary | D10: First Claim | E10: FALSE | F10: Veteran | G10: 16 | H10: 46125
A11: 1135 | B11: Askham | C11: Simon | D11: First Claim | E11: FALSE | F11: Veteran | G11: 1 | H11: 46125
A12: 982 | B12: Bacon | C12: Steve | D12: First Claim | E12: FALSE | F12: Veteran | G12: 22 | H12: 46125
A13: 1328 | B13: Bailey | C13: Shaun | D13: First Claim | E13: FALSE | F13: Veteran | G13: 4 | H13: 46125
A14: 369 | B14: Barnett | C14: Dean | D14: First Claim | E14: FALSE | F14: Veteran | G14: 8 | H14: 46125
A15: 7 | B15: Barnett | C15: Vic | D15: Honorary | E15: FALSE | F15: Veteran | G15: 32 | H15: 46125
A16: 473 | B16: Barnett | C16: George | D16: Honorary | E16: FALSE | F16: Veteran | G16: 33 | H16: 46125
A17: 1384 | B17: Barrett | C17: Paul | D17: First Claim | E17: FALSE | F17: Veteran | G17: 30 | H17: 46125
A18: 1348 | B18: Baxter | C18: Lydia | D18: Second Claim | E18: TRUE | F18: Senior | H18: 46125
A19: 1275 | B19: Baxter | C19: Sylvia | D19: First Claim | E19: TRUE | F19: Juvenile | H19: 46125
A20: 68 | B20: Beach | C20: Ronald | D20: Honorary | E20: FALSE | F20: Veteran | G20: 35 | H20: 46125
A21: 1035 | B21: Bell | C21: Peter | D21: First Claim | E21: FALSE | F21: Veteran | G21: 6 | H21: 46125
A22: 1416 | B22: Bellamy | C22: Henry | D22: First Claim | E22: FALSE | F22: Senior | H22: 46125
A23: 1326 | B23: Bennis | C23: Laoise | D23: First Claim | E23: TRUE | F23: Senior | H23: 46125
A24: 477 | B24: Birch | C24: Carol | D24: First Claim | E24: TRUE | F24: Veteran | G24: 34 | H24: 46125
A25: 10 | B25: Birch | C25: Dave | D25: Honorary | E25: FALSE | F25: Veteran | G25: 35 | H25: 46125
A26: 1414 | B26: Boney | C26: Allen | D26: First Claim | E26: FALSE | F26: Veteran | G26: 13 | H26: 46125
A27: 1029 | B27: Bowie | C27: Victor | D27: First Claim | E27: FALSE | F27: Veteran | G27: 28 | H27: 46125
A28: 13 | B28: Bramford | C28: Paul | D28: First Claim | E28: FALSE | F28: Veteran | G28: 28 | H28: 46125
A29: 1255 | B29: Bridgstock | C29: Anne | D29: First Claim | E29: TRUE | F29: Veteran | G29: 13 | H29: 46125
A30: 1405 | B30: Brinkman | C30: Elise | D30: First Claim | E30: TRUE | F30: Juvenile | H30: 46125
A31: 1421 | B31: Brown | C31: Gill | D31: First Claim | E31: TRUE | F31: Veteran | G31: 12 | H31: 46125
A32: 1418 | B32: Brown | C32: James | D32: First Claim | E32: FALSE | F32: Senior | H32: 46125
A33: 919 | B33: Brundell | C33: Paul | D33: First Claim | E33: FALSE | F33: Veteran | G33: 16 | H33: 46125
A34: 1319 | B34: Burgess | C34: Steve | D34: First Claim | E34: FALSE | F34: Veteran | G34: 9 | H34: 46125
A35: 1389 | B35: Campbell | C35: Billy | D35: First Claim | E35: FALSE | F35: Senior | H35: 46125
A36: 940 | B36: Chapman | C36: Alison | D36: First Claim | E36: TRUE | F36: Veteran | G36: 9 | H36: 46125
A37: 806 | B37: Chapman | C37: Mark | D37: First Claim | E37: FALSE | F37: Veteran | G37: 11 | H37: 46125
A38: 482 | B38: Clarke | C38: Nick | D38: First Claim | E38: FALSE | F38: Veteran | G38: 13 | H38: 46125
A39: 674 | B39: Clegg | C39: Jennifer | D39: Second Claim | E39: TRUE | F39: Veteran | G39: 23 | H39: 46125
A40: 1061 | B40: Collis | C40: Daryl | D40: First Claim | E40: FALSE | F40: Veteran | G40: 19 | H40: 46125
...

Sheet 0512_competitors_2026
A1: ClubNumber | B1: Surname | C1: GivenName | D1: ClaimStatus | E1: isFemale | F1: AgeGroup | G1: VetsBucket | H1: ImportDate
A2: 1327 | B2: Abbott | C2: James | D2: First Claim | E2: False | F2: Senior | H2: 46154
A3: 1237 | B3: Abbott | C3: John | D3: First Claim | E3: False | F3: Veteran | G3: 1 | H3: 46154
A4: 819 | B4: Akoslovski | C4: Kath | D4: First Claim | E4: True | F4: Veteran | G4: 23 | H4: 46154
A5: 2 | B5: Alden | C5: Steve | D5: First Claim | E5: False | F5: Veteran | G5: 21 | H5: 46154
A6: 1370 | B6: Aldridge | C6: Ian | D6: First Claim | E6: False | F6: Veteran | G6: 4 | H6: 46154
A7: 1415 | B7: Aldridge | C7: James | D7: First Claim | E7: False | F7: Juvenile | H7: 46154
A8: 1286 | B8: Allen | C8: Ian | D8: First Claim | E8: False | F8: Veteran | G8: 13 | H8: 46154
A9: 1381 | B9: Allen | C9: Roland | D9: First Claim | E9: False | F9: Senior | H9: 46154
A10: 1112 | B10: Ashwell | C10: Gary | D10: First Claim | E10: False | F10: Veteran | G10: 16 | H10: 46154
A11: 1135 | B11: Askham | C11: Simon | D11: First Claim | E11: False | F11: Veteran | G11: 1 | H11: 46154
A12: 982 | B12: Bacon | C12: Steve | D12: First Claim | E12: False | F12: Veteran | G12: 22 | H12: 46154
A13: 1328 | B13: Bailey | C13: Shaun | D13: First Claim | E13: False | F13: Veteran | G13: 4 | H13: 46154
A14: 369 | B14: Barnett | C14: Dean | D14: First Claim | E14: False | F14: Veteran | G14: 8 | H14: 46154
A15: 7 | B15: Barnett | C15: Vic | D15: Honorary | E15: False | F15: Veteran | G15: 32 | H15: 46154
A16: 473 | B16: Barnett | C16: George | D16: Honorary | E16: False | F16: Veteran | G16: 33 | H16: 46154
A17: 1384 | B17: Barrett | C17: Paul | D17: First Claim | E17: False | F17: Veteran | G17: 30 | H17: 46154
A18: 1348 | B18: Baxter | C18: Lydia | D18: Second Claim | E18: True | F18: Senior | H18: 46154
A19: 1275 | B19: Baxter | C19: Sylvia | D19: First Claim | E19: True | F19: Juvenile | H19: 46154
A20: 68 | B20: Beach | C20: Ronald | D20: Honorary | E20: False | F20: Veteran | G20: 35 | H20: 46154
A21: 1035 | B21: Bell | C21: Peter | D21: First Claim | E21: False | F21: Veteran | G21: 6 | H21: 46154
A22: 1416 | B22: Bellamy | C22: Henry | D22: First Claim | E22: False | F22: Senior | H22: 46154
A23: 1326 | B23: Bennis | C23: Laoise | D23: First Claim | E23: True | F23: Senior | H23: 46154
A24: 477 | B24: Birch | C24: Carol | D24: First Claim | E24: True | F24: Veteran | G24: 34 | H24: 46154
A25: 10 | B25: Birch | C25: Dave | D25: Honorary | E25: False | F25: Veteran | G25: 35 | H25: 46154
A26: 1414 | B26: Boney | C26: Allen | D26: First Claim | E26: False | F26: Veteran | G26: 13 | H26: 46154
A27: 1029 | B27: Bowie | C27: Victor | D27: First Claim | E27: False | F27: Veteran | G27: 28 | H27: 46154
A28: 13 | B28: Bramford | C28: Paul | D28: First Claim | E28: False | F28: Veteran | G28: 28 | H28: 46154
A29: 1255 | B29: Bridgstock | C29: Anne | D29: First Claim | E29: True | F29: Veteran | G29: 13 | H29: 46154
A30: 1405 | B30: Brinkman | C30: Elise | D30: First Claim | E30: True | F30: Juvenile | H30: 46154
A31: 1421 | B31: Brown | C31: Gill | D31: First Claim | E31: True | F31: Veteran | G31: 12 | H31: 46154
A32: 1418 | B32: Brown | C32: James | D32: First Claim | E32: False | F32: Senior | H32: 46154
A33: 919 | B33: Brundell | C33: Paul | D33: First Claim | E33: False | F33: Veteran | G33: 16 | H33: 46154
A34: 1319 | B34: Burgess | C34: Steve | D34: First Claim | E34: False | F34: Veteran | G34: 9 | H34: 46154
A35: 1389 | B35: Campbell | C35: Billy | D35: First Claim | E35: False | F35: Senior | H35: 46154
A36: 940 | B36: Chapman | C36: Alison | D36: First Claim | E36: True | F36: Veteran | G36: 9 | H36: 46154
A37: 806 | B37: Chapman | C37: Mark | D37: First Claim | E37: False | F37: Veteran | G37: 11 | H37: 46154
A38: 482 | B38: Clarke | C38: Nick | D38: First Claim | E38: False | F38: Veteran | G38: 13 | H38: 46154
A39: 674 | B39: Clegg | C39: Jennifer | D39: Second Claim | E39: True | F39: Veteran | G39: 23 | H39: 46154
A40: 1061 | B40: Collis | C40: Daryl | D40: First Claim | E40: False | F40: Veteran | G40: 19 | H40: 46154
...

Sheet 0515_competitors_2026
A1: ClubNumber | B1: Surname | C1: GivenName | D1: ClaimStatus | E1: isFemale | F1: AgeGroup | G1: VetsBucket | H1: ImportDate
A2: 1327 | B2: Abbott | C2: James | D2: First Claim | E2: False | F2: Senior | H2: 46157
A3: 1237 | B3: Abbott | C3: John | D3: First Claim | E3: False | F3: Veteran | G3: 1 | H3: 46157
A4: 819 | B4: Akoslovski | C4: Kath | D4: First Claim | E4: True | F4: Veteran | G4: 23 | H4: 46157
A5: 2 | B5: Alden | C5: Steve | D5: First Claim | E5: False | F5: Veteran | G5: 21 | H5: 46157
A6: 1370 | B6: Aldridge | C6: Ian | D6: First Claim | E6: False | F6: Veteran | G6: 4 | H6: 46157
A7: 1415 | B7: Aldridge | C7: James | D7: First Claim | E7: False | F7: Juvenile | H7: 46157
A8: 1286 | B8: Allen | C8: Ian | D8: First Claim | E8: False | F8: Veteran | G8: 13 | H8: 46157
A9: 1381 | B9: Allen | C9: Roland | D9: First Claim | E9: False | F9: Senior | H9: 46157
A10: 1112 | B10: Ashwell | C10: Gary | D10: First Claim | E10: False | F10: Veteran | G10: 16 | H10: 46157
A11: 1135 | B11: Askham | C11: Simon | D11: First Claim | E11: False | F11: Veteran | G11: 1 | H11: 46157
A12: 982 | B12: Bacon | C12: Steve | D12: First Claim | E12: False | F12: Veteran | G12: 22 | H12: 46157
A13: 1328 | B13: Bailey | C13: Shaun | D13: First Claim | E13: False | F13: Veteran | G13: 4 | H13: 46157
A14: 369 | B14: Barnett | C14: Dean | D14: First Claim | E14: False | F14: Veteran | G14: 8 | H14: 46157
A15: 7 | B15: Barnett | C15: Vic | D15: Honorary | E15: False | F15: Veteran | G15: 32 | H15: 46157
A16: 473 | B16: Barnett | C16: George | D16: Honorary | E16: False | F16: Veteran | G16: 33 | H16: 46157
A17: 1384 | B17: Barrett | C17: Paul | D17: First Claim | E17: False | F17: Veteran | G17: 30 | H17: 46157
A18: 1348 | B18: Baxter | C18: Lydia | D18: Second Claim | E18: True | F18: Senior | H18: 46157
A19: 1275 | B19: Baxter | C19: Sylvia | D19: First Claim | E19: True | F19: Juvenile | H19: 46157
A20: 68 | B20: Beach | C20: Ronald | D20: Honorary | E20: False | F20: Veteran | G20: 35 | H20: 46157
A21: 1035 | B21: Bell | C21: Peter | D21: First Claim | E21: False | F21: Veteran | G21: 6 | H21: 46157
A22: 1416 | B22: Bellamy | C22: Henry | D22: First Claim | E22: False | F22: Senior | H22: 46157
A23: 1326 | B23: Bennis | C23: Laoise | D23: First Claim | E23: True | F23: Senior | H23: 46157
A24: 477 | B24: Birch | C24: Carol | D24: First Claim | E24: True | F24: Veteran | G24: 34 | H24: 46157
A25: 10 | B25: Birch | C25: Dave | D25: Honorary | E25: False | F25: Veteran | G25: 35 | H25: 46157
A26: 1414 | B26: Boney | C26: Allen | D26: First Claim | E26: False | F26: Veteran | G26: 13 | H26: 46157
A27: 1029 | B27: Bowie | C27: Victor | D27: First Claim | E27: False | F27: Veteran | G27: 28 | H27: 46157
A28: 13 | B28: Bramford | C28: Paul | D28: First Claim | E28: False | F28: Veteran | G28: 28 | H28: 46157
A29: 1255 | B29: Bridgstock | C29: Anne | D29: First Claim | E29: True | F29: Veteran | G29: 13 | H29: 46157
A30: 1405 | B30: Brinkman | C30: Elise | D30: First Claim | E30: True | F30: Juvenile | H30: 46157
A31: 1421 | B31: Brown | C31: Gill | D31: First Claim | E31: True | F31: Veteran | G31: 12 | H31: 46157
A32: 1418 | B32: Brown | C32: James | D32: First Claim | E32: False | F32: Senior | H32: 46157
A33: 919 | B33: Brundell | C33: Paul | D33: First Claim | E33: False | F33: Veteran | G33: 16 | H33: 46157
A34: 1319 | B34: Burgess | C34: Steve | D34: First Claim | E34: False | F34: Veteran | G34: 9 | H34: 46157
A35: 1389 | B35: Campbell | C35: Billy | D35: First Claim | E35: False | F35: Senior | H35: 46157
A36: 940 | B36: Chapman | C36: Alison | D36: First Claim | E36: True | F36: Veteran | G36: 9 | H36: 46157
A37: 806 | B37: Chapman | C37: Mark | D37: First Claim | E37: False | F37: Veteran | G37: 11 | H37: 46157
A38: 482 | B38: Clarke | C38: Nick | D38: First Claim | E38: False | F38: Veteran | G38: 13 | H38: 46157
A39: 674 | B39: Clegg | C39: Jennifer | D39: Second Claim | E39: True | F39: Veteran | G39: 23 | H39: 46157
A40: 1061 | B40: Collis | C40: Daryl | D40: First Claim | E40: False | F40: Veteran | G40: 19 | H40: 46157
...

Sheet 0517_competitors_2026
A1: ClubNumber | B1: Surname | C1: GivenName | D1: ClaimStatus | E1: isFemale | F1: AgeGroup | G1: VetsBucket | H1: ImportDate
A2: 1327 | B2: Abbott | C2: James | D2: First Claim | E2: False | F2: Senior | H2: 46159
A3: 1237 | B3: Abbott | C3: John | D3: First Claim | E3: False | F3: Veteran | G3: 1 | H3: 46159
A4: 819 | B4: Akoslovski | C4: Kath | D4: First Claim | E4: True | F4: Veteran | G4: 23 | H4: 46159
A5: 2 | B5: Alden | C5: Steve | D5: First Claim | E5: False | F5: Veteran | G5: 21 | H5: 46159
A6: 1370 | B6: Aldridge | C6: Ian | D6: First Claim | E6: False | F6: Veteran | G6: 4 | H6: 46159
A7: 1415 | B7: Aldridge | C7: James | D7: First Claim | E7: False | F7: Juvenile | H7: 46159
A8: 1286 | B8: Allen | C8: Ian | D8: First Claim | E8: False | F8: Veteran | G8: 13 | H8: 46159
A9: 1381 | B9: Allen | C9: Roland | D9: First Claim | E9: False | F9: Senior | H9: 46159
A10: 1112 | B10: Ashwell | C10: Gary | D10: First Claim | E10: False | F10: Veteran | G10: 16 | H10: 46159
A11: 1135 | B11: Askham | C11: Simon | D11: First Claim | E11: False | F11: Veteran | G11: 1 | H11: 46159
A12: 982 | B12: Bacon | C12: Steve | D12: First Claim | E12: False | F12: Veteran | G12: 22 | H12: 46159
A13: 1328 | B13: Bailey | C13: Shaun | D13: First Claim | E13: False | F13: Veteran | G13: 4 | H13: 46159
A14: 369 | B14: Barnett | C14: Dean | D14: First Claim | E14: False | F14: Veteran | G14: 8 | H14: 46159
A15: 7 | B15: Barnett | C15: Vic | D15: Honorary | E15: False | F15: Veteran | G15: 32 | H15: 46159
A16: 473 | B16: Barnett | C16: George | D16: Honorary | E16: False | F16: Veteran | G16: 33 | H16: 46159
A17: 1384 | B17: Barrett | C17: Paul | D17: First Claim | E17: False | F17: Veteran | G17: 30 | H17: 46159
A18: 1348 | B18: Baxter | C18: Lydia | D18: Second Claim | E18: True | F18: Senior | H18: 46159
A19: 1275 | B19: Baxter | C19: Sylvia | D19: First Claim | E19: True | F19: Juvenile | H19: 46159
A20: 68 | B20: Beach | C20: Ronald | D20: Honorary | E20: False | F20: Veteran | G20: 35 | H20: 46159
A21: 1035 | B21: Bell | C21: Peter | D21: First Claim | E21: False | F21: Veteran | G21: 6 | H21: 46159
A22: 1416 | B22: Bellamy | C22: Henry | D22: First Claim | E22: False | F22: Senior | H22: 46159
A23: 1326 | B23: Bennis | C23: Laoise | D23: First Claim | E23: True | F23: Senior | H23: 46159
A24: 477 | B24: Birch | C24: Carol | D24: First Claim | E24: True | F24: Veteran | G24: 34 | H24: 46159
A25: 10 | B25: Birch | C25: Dave | D25: Honorary | E25: False | F25: Veteran | G25: 35 | H25: 46159
A26: 1414 | B26: Boney | C26: Allen | D26: First Claim | E26: False | F26: Veteran | G26: 13 | H26: 46159
A27: 1029 | B27: Bowie | C27: Victor | D27: First Claim | E27: False | F27: Veteran | G27: 28 | H27: 46159
A28: 13 | B28: Bramford | C28: Paul | D28: First Claim | E28: False | F28: Veteran | G28: 28 | H28: 46159
A29: 1255 | B29: Bridgstock | C29: Anne | D29: First Claim | E29: True | F29: Veteran | G29: 13 | H29: 46159
A30: 1405 | B30: Brinkman | C30: Elise | D30: First Claim | E30: True | F30: Juvenile | H30: 46159
A31: 1421 | B31: Brown | C31: Gill | D31: First Claim | E31: True | F31: Veteran | G31: 12 | H31: 46159
A32: 1418 | B32: Brown | C32: James | D32: First Claim | E32: False | F32: Senior | H32: 46159
A33: 919 | B33: Brundell | C33: Paul | D33: First Claim | E33: False | F33: Veteran | G33: 16 | H33: 46159
A34: 1319 | B34: Burgess | C34: Steve | D34: First Claim | E34: False | F34: Veteran | G34: 9 | H34: 46159
A35: 1389 | B35: Campbell | C35: Billy | D35: First Claim | E35: False | F35: Senior | H35: 46159
A36: 940 | B36: Chapman | C36: Alison | D36: First Claim | E36: True | F36: Veteran | G36: 9 | H36: 46159
A37: 806 | B37: Chapman | C37: Mark | D37: First Claim | E37: False | F37: Veteran | G37: 11 | H37: 46159
A38: 482 | B38: Clarke | C38: Nick | D38: First Claim | E38: False | F38: Veteran | G38: 13 | H38: 46159
A39: 674 | B39: Clegg | C39: Jennifer | D39: Second Claim | E39: True | F39: Veteran | G39: 23 | H39: 46159
A40: 1061 | B40: Collis | C40: Daryl | D40: First Claim | E40: False | F40: Veteran | G40: 19 | H40: 46159
...

Sheet 0601_competitors_2026
A1: ClubNumber | B1: Surname | C1: GivenName | D1: ClaimStatus | E1: isFemale | F1: AgeGroup | G1: VetsBucket | H1: ImportDate
A2: 1327 | B2: Abbott | C2: James | D2: First Claim | E2: False | F2: Senior | H2: 46174
A3: 1237 | B3: Abbott | C3: John | D3: First Claim | E3: False | F3: Veteran | G3: 1 | H3: 46174
A4: 819 | B4: Akoslovski | C4: Kath | D4: First Claim | E4: True | F4: Veteran | G4: 23 | H4: 46174
A5: 2 | B5: Alden | C5: Steve | D5: First Claim | E5: False | F5: Veteran | G5: 21 | H5: 46174
A6: 1370 | B6: Aldridge | C6: Ian | D6: First Claim | E6: False | F6: Veteran | G6: 4 | H6: 46174
A7: 1415 | B7: Aldridge | C7: James | D7: First Claim | E7: False | F7: Juvenile | H7: 46174
A8: 1286 | B8: Allen | C8: Ian | D8: First Claim | E8: False | F8: Veteran | G8: 13 | H8: 46174
A9: 1381 | B9: Allen | C9: Roland | D9: First Claim | E9: False | F9: Senior | H9: 46174
A10: 1112 | B10: Ashwell | C10: Gary | D10: First Claim | E10: False | F10: Veteran | G10: 16 | H10: 46174
A11: 1135 | B11: Askham | C11: Simon | D11: First Claim | E11: False | F11: Veteran | G11: 1 | H11: 46174
A12: 982 | B12: Bacon | C12: Steve | D12: First Claim | E12: False | F12: Veteran | G12: 22 | H12: 46174
A13: 1328 | B13: Bailey | C13: Shaun | D13: First Claim | E13: False | F13: Veteran | G13: 4 | H13: 46174
A14: 369 | B14: Barnett | C14: Dean | D14: First Claim | E14: False | F14: Veteran | G14: 8 | H14: 46174
A15: 7 | B15: Barnett | C15: Vic | D15: Honorary | E15: False | F15: Veteran | G15: 32 | H15: 46174
A16: 473 | B16: Barnett | C16: George | D16: Honorary | E16: False | F16: Veteran | G16: 33 | H16: 46174
A17: 1384 | B17: Barrett | C17: Paul | D17: First Claim | E17: False | F17: Veteran | G17: 30 | H17: 46174
A18: 1348 | B18: Baxter | C18: Lydia | D18: Second Claim | E18: True | F18: Senior | H18: 46174
A19: 1275 | B19: Baxter | C19: Sylvia | D19: First Claim | E19: True | F19: Juvenile | H19: 46174
A20: 68 | B20: Beach | C20: Ronald | D20: Honorary | E20: False | F20: Veteran | G20: 35 | H20: 46174
A21: 1035 | B21: Bell | C21: Peter | D21: First Claim | E21: False | F21: Veteran | G21: 6 | H21: 46174
A22: 1416 | B22: Bellamy | C22: Henry | D22: First Claim | E22: False | F22: Senior | H22: 46174
A23: 1326 | B23: Bennis | C23: Laoise | D23: First Claim | E23: True | F23: Senior | H23: 46174
A24: 477 | B24: Birch | C24: Carol | D24: First Claim | E24: True | F24: Veteran | G24: 34 | H24: 46174
A25: 10 | B25: Birch | C25: Dave | D25: Honorary | E25: False | F25: Veteran | G25: 35 | H25: 46174
A26: 1414 | B26: Boney | C26: Allen | D26: First Claim | E26: False | F26: Veteran | G26: 13 | H26: 46174
A27: 1029 | B27: Bowie | C27: Victor | D27: First Claim | E27: False | F27: Veteran | G27: 28 | H27: 46174
A28: 13 | B28: Bramford | C28: Paul | D28: First Claim | E28: False | F28: Veteran | G28: 28 | H28: 46174
A29: 1255 | B29: Bridgstock | C29: Anne | D29: First Claim | E29: True | F29: Veteran | G29: 13 | H29: 46174
A30: 1405 | B30: Brinkman | C30: Elise | D30: First Claim | E30: True | F30: Juvenile | H30: 46174
A31: 1421 | B31: Brown | C31: Gill | D31: First Claim | E31: True | F31: Veteran | G31: 12 | H31: 46174
A32: 1418 | B32: Brown | C32: James | D32: First Claim | E32: False | F32: Senior | H32: 46174
A33: 919 | B33: Brundell | C33: Paul | D33: First Claim | E33: False | F33: Veteran | G33: 16 | H33: 46174
A34: 1319 | B34: Burgess | C34: Steve | D34: First Claim | E34: False | F34: Veteran | G34: 9 | H34: 46174
A35: 1389 | B35: Campbell | C35: Billy | D35: First Claim | E35: False | F35: Senior | H35: 46174
A36: 940 | B36: Chapman | C36: Alison | D36: First Claim | E36: True | F36: Veteran | G36: 9 | H36: 46174
A37: 806 | B37: Chapman | C37: Mark | D37: First Claim | E37: False | F37: Veteran | G37: 11 | H37: 46174
A38: 482 | B38: Clarke | C38: Nick | D38: First Claim | E38: False | F38: Veteran | G38: 13 | H38: 46174
A39: 674 | B39: Clegg | C39: Jennifer | D39: Second Claim | E39: True | F39: Veteran | G39: 23 | H39: 46174
A40: 1061 | B40: Collis | C40: Daryl | D40: First Claim | E40: False | F40: Veteran | G40: 19 | H40: 46174
...

Sheet 0608_competitors_2026
A1: ClubNumber | B1: Surname | C1: GivenName | D1: ClaimStatus | E1: isFemale | F1: AgeGroup | G1: VetsBucket | H1: ImportDate
A2: 1327 | B2: Abbott | C2: James | D2: First Claim | E2: False | F2: Senior | H2: 46181
A3: 1237 | B3: Abbott | C3: John | D3: First Claim | E3: False | F3: Veteran | G3: 1 | H3: 46181
A4: 819 | B4: Akoslovski | C4: Kath | D4: First Claim | E4: True | F4: Veteran | G4: 23 | H4: 46181
A5: 2 | B5: Alden | C5: Steve | D5: First Claim | E5: False | F5: Veteran | G5: 21 | H5: 46181
A6: 1370 | B6: Aldridge | C6: Ian | D6: First Claim | E6: False | F6: Veteran | G6: 4 | H6: 46181
A7: 1415 | B7: Aldridge | C7: James | D7: First Claim | E7: False | F7: Juvenile | H7: 46181
A8: 1286 | B8: Allen | C8: Ian | D8: First Claim | E8: False | F8: Veteran | G8: 13 | H8: 46181
A9: 1381 | B9: Allen | C9: Roland | D9: First Claim | E9: False | F9: Senior | H9: 46181
A10: 1112 | B10: Ashwell | C10: Gary | D10: First Claim | E10: False | F10: Veteran | G10: 16 | H10: 46181
A11: 1135 | B11: Askham | C11: Simon | D11: First Claim | E11: False | F11: Veteran | G11: 1 | H11: 46181
A12: 982 | B12: Bacon | C12: Steve | D12: First Claim | E12: False | F12: Veteran | G12: 22 | H12: 46181
A13: 1328 | B13: Bailey | C13: Shaun | D13: First Claim | E13: False | F13: Veteran | G13: 4 | H13: 46181
A14: 369 | B14: Barnett | C14: Dean | D14: First Claim | E14: False | F14: Veteran | G14: 8 | H14: 46181
A15: 7 | B15: Barnett | C15: Vic | D15: Honorary | E15: False | F15: Veteran | G15: 32 | H15: 46181
A16: 473 | B16: Barnett | C16: George | D16: Honorary | E16: False | F16: Veteran | G16: 33 | H16: 46181
A17: 1384 | B17: Barrett | C17: Paul | D17: First Claim | E17: False | F17: Veteran | G17: 30 | H17: 46181
A18: 1348 | B18: Baxter | C18: Lydia | D18: Second Claim | E18: True | F18: Senior | H18: 46181
A19: 1275 | B19: Baxter | C19: Sylvia | D19: First Claim | E19: True | F19: Juvenile | H19: 46181
A20: 68 | B20: Beach | C20: Ronald | D20: Honorary | E20: False | F20: Veteran | G20: 35 | H20: 46181
A21: 1035 | B21: Bell | C21: Peter | D21: First Claim | E21: False | F21: Veteran | G21: 6 | H21: 46181
A22: 1416 | B22: Bellamy | C22: Henry | D22: First Claim | E22: False | F22: Senior | H22: 46181
A23: 1326 | B23: Bennis | C23: Laoise | D23: First Claim | E23: True | F23: Senior | H23: 46181
A24: 477 | B24: Birch | C24: Carol | D24: First Claim | E24: True | F24: Veteran | G24: 34 | H24: 46181
A25: 10 | B25: Birch | C25: Dave | D25: Honorary | E25: False | F25: Veteran | G25: 35 | H25: 46181
A26: 1414 | B26: Boney | C26: Allen | D26: First Claim | E26: False | F26: Veteran | G26: 13 | H26: 46181
A27: 1029 | B27: Bowie | C27: Victor | D27: First Claim | E27: False | F27: Veteran | G27: 28 | H27: 46181
A28: 13 | B28: Bramford | C28: Paul | D28: First Claim | E28: False | F28: Veteran | G28: 28 | H28: 46181
A29: 1255 | B29: Bridgstock | C29: Anne | D29: First Claim | E29: True | F29: Veteran | G29: 13 | H29: 46181
A30: 1405 | B30: Brinkman | C30: Elise | D30: First Claim | E30: True | F30: Juvenile | H30: 46181
A31: 1421 | B31: Brown | C31: Gill | D31: First Claim | E31: True | F31: Veteran | G31: 12 | H31: 46181
A32: 1418 | B32: Brown | C32: James | D32: First Claim | E32: False | F32: Senior | H32: 46181
A33: 919 | B33: Brundell | C33: Paul | D33: First Claim | E33: False | F33: Veteran | G33: 16 | H33: 46181
A34: 1319 | B34: Burgess | C34: Steve | D34: First Claim | E34: False | F34: Veteran | G34: 9 | H34: 46181
A35: 1389 | B35: Campbell | C35: Billy | D35: First Claim | E35: False | F35: Senior | H35: 46181
A36: 940 | B36: Chapman | C36: Alison | D36: First Claim | E36: True | F36: Veteran | G36: 9 | H36: 46181
A37: 806 | B37: Chapman | C37: Mark | D37: First Claim | E37: False | F37: Veteran | G37: 11 | H37: 46181
A38: 482 | B38: Clarke | C38: Nick | D38: First Claim | E38: False | F38: Veteran | G38: 13 | H38: 46181
A39: 674 | B39: Clegg | C39: Jennifer | D39: Second Claim | E39: True | F39: Veteran | G39: 23 | H39: 46181
A40: 1061 | B40: Collis | C40: Daryl | D40: First Claim | E40: False | F40: Veteran | G40: 19 | H40: 46181
...

Sheet 0623_competitors_2026
A1: ClubNumber | B1: Surname | C1: GivenName | D1: ClaimStatus | E1: isFemale | F1: AgeGroup | G1: VetsBucket | H1: ImportDate
A2: 1327 | B2: Abbott | C2: James | D2: First Claim | E2: FALSE | F2: Senior | H2: 46196
A3: 1237 | B3: Abbott | C3: John | D3: First Claim | E3: FALSE | F3: Veteran | G3: 1 | H3: 46196
A4: 819 | B4: Akoslovski | C4: Kath | D4: First Claim | E4: TRUE | F4: Veteran | G4: 23 | H4: 46196
A5: 2 | B5: Alden | C5: Steve | D5: First Claim | E5: FALSE | F5: Veteran | G5: 21 | H5: 46196
A6: 1370 | B6: Aldridge | C6: Ian | D6: First Claim | E6: FALSE | F6: Veteran | G6: 4 | H6: 46196
A7: 1415 | B7: Aldridge | C7: James | D7: First Claim | E7: FALSE | F7: Juvenile | H7: 46196
A8: 1286 | B8: Allen | C8: Ian | D8: First Claim | E8: FALSE | F8: Veteran | G8: 13 | H8: 46196
A9: 1381 | B9: Allen | C9: Roland | D9: First Claim | E9: FALSE | F9: Senior | H9: 46196
A10: 1112 | B10: Ashwell | C10: Gary | D10: First Claim | E10: FALSE | F10: Veteran | G10: 16 | H10: 46196
A11: 1135 | B11: Askham | C11: Simon | D11: First Claim | E11: FALSE | F11: Veteran | G11: 1 | H11: 46196
A12: 1430 | B12: Bacon | C12: Gary | D12: First Claim | E12: FALSE | F12: Veteran | G12: 4 | H12: 46196
A13: 982 | B13: Bacon | C13: Steve | D13: First Claim | E13: FALSE | F13: Veteran | G13: 22 | H13: 46196
A14: 1328 | B14: Bailey | C14: Shaun | D14: First Claim | E14: FALSE | F14: Veteran | G14: 4 | H14: 46196
A15: 369 | B15: Barnett | C15: Dean | D15: First Claim | E15: FALSE | F15: Veteran | G15: 8 | H15: 46196
A16: 7 | B16: Barnett | C16: Vic | D16: Honorary | E16: FALSE | F16: Veteran | G16: 32 | H16: 46196
A17: 473 | B17: Barnett | C17: George | D17: Honorary | E17: FALSE | F17: Veteran | G17: 33 | H17: 46196
A18: 1384 | B18: Barrett | C18: Paul | D18: First Claim | E18: FALSE | F18: Veteran | G18: 30 | H18: 46196
A19: 1348 | B19: Baxter | C19: Lydia | D19: Second Claim | E19: TRUE | F19: Senior | H19: 46196
A20: 1275 | B20: Baxter | C20: Sylvia | D20: First Claim | E20: TRUE | F20: Juvenile | H20: 46196
A21: 68 | B21: Beach | C21: Ronald | D21: Honorary | E21: FALSE | F21: Veteran | G21: 35 | H21: 46196
A22: 1035 | B22: Bell | C22: Peter | D22: First Claim | E22: FALSE | F22: Veteran | G22: 6 | H22: 46196
A23: 1416 | B23: Bellamy | C23: Henry | D23: First Claim | E23: FALSE | F23: Senior | H23: 46196
A24: 1326 | B24: Bennis | C24: Laoise | D24: First Claim | E24: TRUE | F24: Senior | H24: 46196
A25: 1431 | B25: Bewick | C25: Angela | D25: First Claim | E25: TRUE | F25: Veteran | G25: 11 | H25: 46196
A26: 477 | B26: Birch | C26: Carol | D26: First Claim | E26: TRUE | F26: Veteran | G26: 34 | H26: 46196
A27: 10 | B27: Birch | C27: Dave | D27: Honorary | E27: FALSE | F27: Veteran | G27: 35 | H27: 46196
A28: 1414 | B28: Boney | C28: Allen | D28: First Claim | E28: FALSE | F28: Veteran | G28: 13 | H28: 46196
A29: 1029 | B29: Bowie | C29: Victor | D29: First Claim | E29: FALSE | F29: Veteran | G29: 28 | H29: 46196
A30: 13 | B30: Bramford | C30: Paul | D30: First Claim | E30: FALSE | F30: Veteran | G30: 28 | H30: 46196
A31: 1255 | B31: Bridgstock | C31: Anne | D31: First Claim | E31: TRUE | F31: Veteran | G31: 13 | H31: 46196
A32: 1405 | B32: Brinkman | C32: Elise | D32: First Claim | E32: TRUE | F32: Juvenile | H32: 46196
A33: 1421 | B33: Brown | C33: Gill | D33: First Claim | E33: TRUE | F33: Veteran | G33: 12 | H33: 46196
A34: 1418 | B34: Brown | C34: James | D34: First Claim | E34: FALSE | F34: Senior | H34: 46196
A35: 919 | B35: Brundell | C35: Paul | D35: First Claim | E35: FALSE | F35: Veteran | G35: 16 | H35: 46196
A36: 1319 | B36: Burgess | C36: Steve | D36: First Claim | E36: FALSE | F36: Veteran | G36: 9 | H36: 46196
A37: 1389 | B37: Campbell | C37: Billy | D37: First Claim | E37: FALSE | F37: Senior | H37: 46196
A38: 940 | B38: Chapman | C38: Alison | D38: First Claim | E38: TRUE | F38: Veteran | G38: 9 | H38: 46196
A39: 806 | B39: Chapman | C39: Mark | D39: First Claim | E39: FALSE | F39: Veteran | G39: 11 | H39: 46196
A40: 482 | B40: Clarke | C40: Nick | D40: First Claim | E40: FALSE | F40: Veteran | G40: 13 | H40: 46196
...

Sheet 0713_competitors_2026
