Workbook
Name Calendar: Calendar!$A$2:$G$27
Name CalendarEventNumbers: Calendar!$A$2:$A$27
Name ClubNames: NameLookup!$B$2:$B$402
Name ClubNumbers: NameLookup!$A$2:$A$402
Name MemberData: Event_01!$G$2
Name NameToNumber: Event_16!$J$34
Name NonTenEvents: Calendar!$J$2:$J$27
Name Number2Name: NameLookup!$A$2:$B$402
Name RoundRobinNameToClub: RoundRobinRiders!$A$2:$C$26
Name RoundRobinNameToClubRange: RoundRobinRiders!$A$2:$C$157
Name RoundRobinRiderClubs: RoundRobinRiders!$B:$B
Name RoundRobinRiderDecoratedNames: RoundRobinRiders!$C:$C
Name RoundRobinRiderNames: RoundRobinRiders!$A:A
Name RoundRobinRiders: RoundRobinRiders!$A:$A
Name RoundRobinRidersIsFemale: RoundRobinRiders!$D:$D
Name TenMileEvents: Calendar!$K$2:$K$27

Sheet Revisions
A1: 42404 | B1: Mike Ives | C1: Prepared for 2016 season
A2: 45949 | B2: Mike Ives | C2: Created this from the old fully-functional "25 club championship.xlsm"
C3: Removed league and championship sheets - retained just the event sheets
C4: Remove calculated columns from the event sheets
C5: Retains calendar sheet, though I expect this will change
C6: WVCCData sheet is present but needs to be replace by the data from competitors_2025.csv as generated by the private github pipeline from membership .XLSX
A7: 45954 | B7: Mike Ives | C7: Some work on Calendar. Sheets renamed to Event_nn and Hill Climb (seconds have fractions) moved to be Event_01. New column in Calendar sheet indicates which Event_nn sheet is applicable. New isCancelled column added too.
A8: 46046 | B8: Mike Ives | C8: Adds coilumn J in all Events sheets - Raw Name goes here. Column A uses a formula to get Cliub Number, Round Robin Decorated Name (inc club) or just the name.
C9: `=IF(J2="","",XLOOKUP(J2,ClubNames,ClubNumbers,XLOOKUP(J2,RoundRobinRiderNames,RoundRobinRiderDecoratedNames,J2)))

Sheet Competitors
A1: ClubNumber | B1: Surname | C1: GivenName | D1: ClaimStatus | E1: isFemale | F1: AgeGroup | G1: VetsBucket | H1: ImportDate
A2: 1237 | B2: Abbott | C2: John | D2: First Claim | E2: FALSE | F2: Veteran | G2: 1 | H2: 46000
A3: 1327 | B3: Abbott | C3: James | D3: First Claim | E3: FALSE | F3: Senior | H3: 46000
A4: 1197 | B4: Adcock | C4: David | D4: First Claim | E4: FALSE | F4: Veteran | G4: 2 | H4: 46000
A5: 1353 | B5: Ainsley | C5: Emma | D5: First Claim | E5: TRUE | F5: Senior | H5: 46000
A6: 819 | B6: Akoslovski | C6: Kath | D6: First Claim | E6: TRUE | F6: Veteran | G6: 23 | H6: 46000
A7: 2 | B7: Alden | C7: Steve | D7: First Claim | E7: FALSE | F7: Veteran | G7: 21 | H7: 46000
A8: 1370 | B8: Aldridge | C8: Ian | D8: First Claim | E8: FALSE | F8: Veteran | G8: 4 | H8: 46000
A9: 1286 | B9: Allen | C9: Ian | D9: First Claim | E9: FALSE | F9: Veteran | G9: 13 | H9: 46000
A10: 1381 | B10: Allen | C10: Roland | D10: First Claim | E10: FALSE | F10: Senior | H10: 46000
A11: 1153 | B11: Allitt | C11: Chris | D11: First Claim | E11: FALSE | F11: Senior | H11: 46000
A12: 1372 | B12: Andrew | C12: Dan | D12: First Claim | E12: FALSE | F12: Senior | H12: 46000
A13: 1112 | B13: Ashwell | C13: Gary | D13: First Claim | E13: FALSE | F13: Veteran | G13: 16 | H13: 46000
A14: 1135 | B14: Askham | C14: Simon | D14: First Claim | E14: FALSE | F14: Veteran | G14: 1 | H14: 46000
A15: 1368 | B15: Awdry | C15: Ollie | D15: First Claim | E15: FALSE | F15: Juvenile | H15: 46000
A16: 1328 | B16: Bailey | C16: Shaun | D16: First Claim | E16: FALSE | F16: Veteran | G16: 4 | H16: 46000
A17: 369 | B17: Barnett | C17: Dean | D17: First Claim | E17: FALSE | F17: Veteran | G17: 8 | H17: 46000
A18: 7 | B18: Barnett | C18: Vic | D18: Honorary | E18: FALSE | F18: Veteran | G18: 32 | H18: 46000
A19: 473 | B19: Barnett | C19: George | D19: Honorary | E19: FALSE | F19: Veteran | G19: 33 | H19: 46000
A20: 1384 | B20: Barrett | C20: Paul | D20: First Claim | E20: FALSE | F20: Veteran | G20: 30 | H20: 46000
A21: 1348 | B21: Baxter | C21: Lydia | D21: Second Claim | E21: TRUE | F21: Senior | H21: 46000
A22: 1275 | B22: Baxter | C22: Sylvia | D22: First Claim | E22: TRUE | F22: Juvenile | H22: 46000
A23: 68 | B23: Beach | C23: Ronald | D23: Honorary | E23: FALSE | F23: Veteran | G23: 35 | H23: 46000
A24: 1035 | B24: Bell | C24: Peter | D24: First Claim | E24: FALSE | F24: Veteran | G24: 6 | H24: 46000
A25: 1326 | B25: Bennis | C25: Laoise | D25: First Claim | E25: TRUE | F25: Senior | H25: 46000
A26: 10 | B26: Birch | C26: Dave | D26: Honorary | E26: FALSE | F26: Veteran | G26: 35 | H26: 46000
A27: 477 | B27: Birch | C27: Carol | D27: First Claim | E27: TRUE | F27: Veteran | G27: 34 | H27: 46000
A28: 1318 | B28: Blake | C28: Andy | D28: First Claim | E28: FALSE | F28: Veteran | G28: 22 | H28: 46000
A29: 779 | B29: Bosence | C29: Mark | D29: First Claim | E29: FALSE | F29: Veteran | G29: 15 | H29: 46000
A30: 1029 | B30: Bowie | C30: Victor | D30: First Claim | E30: FALSE | F30: Veteran | G30: 28 | H30: 46000
A31: 13 | B31: Bramford | C31: Paul | D31: First Claim | E31: FALSE | F31: Veteran | G31: 28 | H31: 46000
A32: 1255 | B32: Bridgstock | C32: Anne | D32: First Claim | E32: TRUE | F32: Veteran | G32: 13 | H32: 46000
A33: 919 | B33: Brundell | C33: Paul | D33: First Claim | E33: FALSE | F33: Veteran | G33: 16 | H33: 46000
A34: 1190 | B34: Burke | C34: Jacob | D34: First Claim | E34: FALSE | F34: Juvenile | H34: 46000
A35: 1189 | B35: Burke | C35: Max | D35: First Claim | E35: FALSE | F35: Juvenile | H35: 46000
A36: 735 | B36: Burke | C36: Michael | D36: Second Claim | E36: FALSE | F36: Senior | H36: 46000
A37: 1319 | B37: Burgess | C37: Steve | D37: First Claim | E37: FALSE | F37: Veteran | G37: 9 | H37: 46000
A38: 1389 | B38: Campbell | C38: Billy | D38: First Claim | E38: FALSE | F38: Senior | H38: 46000
A39: 1291 | B39: Carter | C39: Jason | D39: First Claim | E39: FALSE | F39: Veteran | G39: 6 | H39: 46000
A40: 940 | B40: Chapman | C40: Alison | D40: First Claim | E40: TRUE | F40: Veteran | G40: 9 | H40: 46000
...

Sheet NameLookup
A1: Number | B1: Full Name
A2: =IF(ISNUMBER(Competitors!A2),Competitors!A2,"") -> 1237 | B2: =IF(A2="","",CONCATENATE(VLOOKUP(A2,Competitors!$A$2:$I$650,3,FALSE)," ",VLOOKUP(A2,Competitors!$A$2:$I$650,2,FALSE))) -> John Abbott
A3: =IF(ISNUMBER(Competitors!A3),Competitors!A3,"") -> 1327 | B3: =IF(A3="","",CONCATENATE(VLOOKUP(A3,Competitors!$A$2:$I$650,3,FALSE)," ",VLOOKUP(A3,Competitors!$A$2:$I$650,2,FALSE))) -> James Abbott
A4: =IF(ISNUMBER(Competitors!A4),Competitors!A4,"") -> 1197 | B4: =IF(A4="","",CONCATENATE(VLOOKUP(A4,Competitors!$A$2:$I$650,3,FALSE)," ",VLOOKUP(A4,Competitors!$A$2:$I$650,2,FALSE))) -> David Adcock
A5: =IF(ISNUMBER(Competitors!A5),Competitors!A5,"") -> 1353 | B5: =IF(A5="","",CONCATENATE(VLOOKUP(A5,Competitors!$A$2:$I$650,3,FALSE)," ",VLOOKUP(A5,Competitors!$A$2:$I$650,2,FALSE))) -> Emma Ainsley
A6: =IF(ISNUMBER(Competitors!A6),Competitors!A6,"") -> 819 | B6: =IF(A6="","",CONCATENATE(VLOOKUP(A6,Competitors!$A$2:$I$650,3,FALSE)," ",VLOOKUP(A6,Competitors!$A$2:$I$650,2,FALSE))) -> Kath Akoslovski
A7: =IF(ISNUMBER(Competitors!A7),Competitors!A7,"") -> 2 | B7: =IF(A7="","",CONCATENATE(VLOOKUP(A7,Competitors!$A$2:$I$650,3,FALSE)," ",VLOOKUP(A7,Competitors!$A$2:$I$650,2,FALSE))) -> Steve Alden
A8: =IF(ISNUMBER(Competitors!A8),Competitors!A8,"") -> 1370 | B8: =IF(A8="","",CONCATENATE(VLOOKUP(A8,Competitors!$A$2:$I$650,3,FALSE)," ",VLOOKUP(A8,Competitors!$A$2:$I$650,2,FALSE))) -> Ian Aldridge
A9: =IF(ISNUMBER(Competitors!A9),Competitors!A9,"") -> 1286 | B9: =IF(A9="","",CONCATENATE(VLOOKUP(A9,Competitors!$A$2:$I$650,3,FALSE)," ",VLOOKUP(A9,Competitors!$A$2:$I$650,2,FALSE))) -> Ian Allen
A10: =IF(ISNUMBER(Competitors!A10),Competitors!A10,"") -> 1381 | B10: =IF(A10="","",CONCATENATE(VLOOKUP(A10,Competitors!$A$2:$I$650,3,FALSE)," ",VLOOKUP(A10,Competitors!$A$2:$I$650,2,FALSE))) -> Roland Allen
A11: =IF(ISNUMBER(Competitors!A11),Competitors!A11,"") -> 1153 | B11: =IF(A11="","",CONCATENATE(VLOOKUP(A11,Competitors!$A$2:$I$650,3,FALSE)," ",VLOOKUP(A11,Competitors!$A$2:$I$650,2,FALSE))) -> Chris Allitt
A12: =IF(ISNUMBER(Competitors!A12),Competitors!A12,"") -> 1372 | B12: =IF(A12="","",CONCATENATE(VLOOKUP(A12,Competitors!$A$2:$I$650,3,FALSE)," ",VLOOKUP(A12,Competitors!$A$2:$I$650,2,FALSE))) -> Dan Andrew
A13: =IF(ISNUMBER(Competitors!A13),Competitors!A13,"") -> 1112 | B13: =IF(A13="","",CONCATENATE(VLOOKUP(A13,Competitors!$A$2:$I$650,3,FALSE)," ",VLOOKUP(A13,Competitors!$A$2:$I$650,2,FALSE))) -> Gary Ashwell
... A402: =IF(ISNUMBER(Competitors!A402),Competitors!A402,"") | B402: =IF(A402="","",CONCATENATE(VLOOKUP(A402,Competitors!$A$2:$I$650,3,FALSE)," ",VLOOKUP(A402,Competitors!$A$2:$I$650,2,FALSE)))

Sheet Calendar
A1: Event Number | B1: Date | C1: Start time | D1: Event Name | E1: Round Robin Club | F1: Miles | G1: Location / Course | H1: Hill Climb | I1: Club Championship | J1: Non-Standard 10 | K1: Evening 10 | L1: Hard Ride Series | M1: Round Robin Event | N1: Sheet Name | O1: isCancelled
A2: 1 | B2: 45748 | C2: 18:30 | D2: Medbourne 9.5mile Hardride TT | F2: 9.5 | G2: Medbourne | I2: Y | J2: =IF($B2="","",IF($F2=10,"","Y")) -> Y | K2: =IF($B2="","",IF($F2=10,"Y","")) | L2: =IF($B2="","",IF(ISNUMBER(SEARCH("Hardride",$D2)),"Y","")) -> Y | N2: ="Event_" & TEXT(A2,"00") -> Event_01
A3: =A2+1 -> 2 | B3: 45753 | C3: 09:00 | D3: Medbourne 9.5mile NDCA Hardride TT | F3: 9.5 | G3: Medbourne | I3: Y | J3: =IF($B3="","",IF($F3=10,"","Y")) -> Y | K3: =IF($B3="","",IF($F3=10,"Y","")) | L3: =IF($B3="","",IF(ISNUMBER(SEARCH("Hardride",$D3)),"Y","")) -> Y | N3: ="Event_" & TEXT(A3,"00") -> Event_02
A4: =A3+1 -> 3 | B4: 45762 | C4: 18:30 | D4: Hallaton 5 5mile TT | F4: 5 | G4: Hallaton 5 | I4: Y | J4: =IF($B4="","",IF($F4=10,"","Y")) -> Y | K4: =IF($B4="","",IF($F4=10,"Y","")) | L4: =IF($B4="","",IF(ISNUMBER(SEARCH("Hardride",$D4)),"Y","")) | N4: ="Event_" & TEXT(A4,"00") -> Event_03
A5: =A4+1 -> 4 | B5: 45767 | C5: 08:00 | D5: Kibworth 25mile TT | F5: 25 | G5: Kibworth | I5: Y | J5: =IF($B5="","",IF($F5=10,"","Y")) -> Y | K5: =IF($B5="","",IF($F5=10,"Y","")) | L5: =IF($B5="","",IF(ISNUMBER(SEARCH("Hardride",$D5)),"Y","")) | N5: ="Event_" & TEXT(A5,"00") -> Event_04
A6: =A5+1 -> 5 | B6: 45776 | C6: 18:30 | D6: Tour of Langtons 10mile TT | F6: 10 | G6: Tour of Langtons | I6: Y | J6: =IF($B6="","",IF($F6=10,"","Y")) | K6: =IF($B6="","",IF($F6=10,"Y","")) -> Y | L6: =IF($B6="","",IF(ISNUMBER(SEARCH("Hardride",$D6)),"Y","")) | N6: ="Event_" & TEXT(A6,"00") -> Event_05
A7: =A6+1 -> 6 | B7: 45783 | C7: 18:30 | D7: Tur Langton/Hallaton 5+5mile TT | F7: =5+5 -> 10 | G7: Tur Langton/Hallaton | I7: Y | J7: Y | K7: ="" | L7: =IF($B7="","",IF(ISNUMBER(SEARCH("Hardride",$D7)),"Y","")) | N7: ="Event_" & TEXT(A7,"00") -> Event_06
A8: =A7+1 -> 7 | B8: 45790 | C8: 19:00 | D8: Tour of Langtons 10mile TT | F8: 10 | G8: Tour of Langtons | I8: Y | J8: =IF($B8="","",IF($F8=10,"","Y")) | K8: =IF($B8="","",IF($F8=10,"Y","")) -> Y | L8: =IF($B8="","",IF(ISNUMBER(SEARCH("Hardride",$D8)),"Y","")) | N8: ="Event_" & TEXT(A8,"00") -> Event_07 | O8: Y
A9: =A8+1 -> 8 | B9: 45804 | C9: 19:00 | D9: Kibworth 10mile TT | F9: 10 | G9: Kibworth | I9: Y | J9: =IF($B9="","",IF($F9=10,"","Y")) | K9: =IF($B9="","",IF($F9=10,"Y","")) -> Y | L9: =IF($B9="","",IF(ISNUMBER(SEARCH("Hardride",$D9)),"Y","")) | N9: ="Event_" & TEXT(A9,"00") -> Event_08
A10: =A9+1 -> 9 | B10: 45809 | C10: 09:00 | D10: Kibworth 25mile TT | F10: 25 | G10: Kibworth | I10: Y | J10: =IF($B10="","",IF($F10=10,"","Y")) -> Y | K10: =IF($B10="","",IF($F10=10,"Y","")) | L10: =IF($B10="","",IF(ISNUMBER(SEARCH("Hardride",$D10)),"Y","")) | N10: ="Event_" & TEXT(A10,"00") -> Event_09
A11: =A10+1 -> 10 | B11: 45818 | C11: 19:30 | D11: Kibworth 10mile TT | F11: 10 | G11: Kibworth | I11: Y | J11: =IF($B11="","",IF($F11=10,"","Y")) | K11: =IF($B11="","",IF($F11=10,"Y","")) -> Y | L11: =IF($B11="","",IF(ISNUMBER(SEARCH("Hardride",$D11)),"Y","")) | N11: ="Event_" & TEXT(A11,"00") -> Event_10
A12: =A11+1 -> 11 | B12: 45823 | C12: 08:00 | D12: Walcote Interclub 25mile Hardride TT | F12: 25 | G12: Walcote | I12: Y | J12: =IF($B12="","",IF($F12=10,"","Y")) -> Y | K12: =IF($B12="","",IF($F12=10,"Y","")) | L12: =IF($B12="","",IF(ISNUMBER(SEARCH("Hardride",$D12)),"Y","")) -> Y | N12: ="Event_" & TEXT(A12,"00") -> Event_11
A13: =A12+1 -> 12 | B13: 45825 | C13: 19:30 | D13: Kibworth 10mile TT | F13: 10 | G13: Kibworth | I13: Y | J13: =IF($B13="","",IF($F13=10,"","Y")) | K13: =IF($B13="","",IF($F13=10,"Y","")) -> Y | L13: =IF($B13="","",IF(ISNUMBER(SEARCH("Hardride",$D13)),"Y","")) | N13: ="Event_" & TEXT(A13,"00") -> Event_12
A14: =A13+1 -> 13 | B14: 45832 | C14: 19:30 | D14: Kibworth 10mile TT | F14: 10 | G14: Kibworth | I14: Y | J14: =IF($B14="","",IF($F14=10,"","Y")) | K14: =IF($B14="","",IF($F14=10,"Y","")) -> Y | L14: =IF($B14="","",IF(ISNUMBER(SEARCH("Hardride",$D14)),"Y","")) | N14: ="Event_" & TEXT(A14,"00") -> Event_13
A15: =A14+1 -> 14 | B15: 45839 | C15: 19:00 | D15: Kibworth 10mile TT | F15: 10 | G15: Kibworth | I15: Y | J15: =IF($B15="","",IF($F15=10,"","Y")) | K15: =IF($B15="","",IF($F15=10,"Y","")) -> Y | L15: =IF($B15="","",IF(ISNUMBER(SEARCH("Hardride",$D15)),"Y","")) | N15: ="Event_" & TEXT(A15,"00") -> Event_14
A16: =A15+1 -> 15 | B16: 45854 | C16: 11:00 | D16: Caldecott 10mile TT | E16: RFW | F16: 10 | G16: Caldecott | I16: Y | J16: =IF($B16="","",IF($F16=10,"","Y")) | K16: =IF($B16="","",IF($F16=10,"Y","")) -> Y | L16: =IF($B16="","",IF(ISNUMBER(SEARCH("Hardride",$D16)),"Y","")) | M16: Y | N16: ="Event_" & TEXT(A16,"00") -> Event_15
A17: =A16+1 -> 16 | B17: 45860 | C17: 19:00 | D17: Lubenham 10mile TT | E17: WVCC | F17: 10 | G17: Lubenham | I17: Y | J17: =IF($B17="","",IF($F17=10,"","Y")) | K17: =IF($B17="","",IF($F17=10,"Y","")) -> Y | L17: =IF($B17="","",IF(ISNUMBER(SEARCH("Hardride",$D17)),"Y","")) | M17: Y | N17: ="Event_" & TEXT(A17,"00") -> Event_16
A18: =A17+1 -> 17 | B18: 45868 | C18: 0.80208333 | D18: Caldecott 10mile TT | E18: RFW | F18: 10 | G18: Caldecott | I18: Y | J18: =IF($B18="","",IF($F18=10,"","Y")) | K18: =IF($B18="","",IF($F18=10,"Y","")) -> Y | L18: =IF($B18="","",IF(ISNUMBER(SEARCH("Hardride",$D18)),"Y","")) | M18: Y | N18: ="Event_" & TEXT(A18,"00") -> Event_17
A19: =A18+1 -> 18 | B19: 45874 | C19: 19:00 | D19: Lubenham 10mile TT | E19: WVCC | F19: 10 | G19: Lubenham | I19: Y | J19: =IF($B19="","",IF($F19=10,"","Y")) | K19: =IF($B19="","",IF($F19=10,"Y","")) -> Y | L19: =IF($B19="","",IF(ISNUMBER(SEARCH("Hardride",$D19)),"Y","")) | M19: Y | N19: ="Event_" & TEXT(A19,"00") -> Event_18
A20: =A19+1 -> 19 | B20: 45881 | C20: 19:00 | D20: Wolvey 10mile TT | E20: HCRC | F20: 10 | G20: Wolvey | I20: Y | J20: =IF($B20="","",IF($F20=10,"","Y")) | K20: =IF($B20="","",IF($F20=10,"Y","")) -> Y | L20: =IF($B20="","",IF(ISNUMBER(SEARCH("Hardride",$D20)),"Y","")) | M20: Y | N20: ="Event_" & TEXT(A20,"00") -> Event_19
A21: =A20+1 -> 20 | B21: 45888 | C21: 19:00 | D21: Wymeswold 10mile TT | E21: LFCC | F21: 10 | G21: Wymeswold | I21: Y | J21: =IF($B21="","",IF($F21=10,"","Y")) | K21: =IF($B21="","",IF($F21=10,"Y","")) -> Y | L21: =IF($B21="","",IF(ISNUMBER(SEARCH("Hardride",$D21)),"Y","")) | M21: Y | N21: ="Event_" & TEXT(A21,"00") -> Event_20
A22: =A21+1 -> 21 | B22: 45895 | C22: 19:00 | D22: Wolvey 10mile TT | E22: HCRC | F22: 10 | G22: Wolvey | I22: Y | J22: =IF($B22="","",IF($F22=10,"","Y")) | K22: =IF($B22="","",IF($F22=10,"Y","")) -> Y | L22: =IF($B22="","",IF(ISNUMBER(SEARCH("Hardride",$D22)),"Y","")) | M22: Y | N22: ="Event_" & TEXT(A22,"00") -> Event_21
A23: =A22+1 -> 22 | B23: 45900 | C23: 09:00 | D23: Tour of Langtons 10mile TT | E23: Ratae,WVCC | F23: 10 | G23: Tour of Langtons | I23: Y | J23: =IF($B23="","",IF($F23=10,"","Y")) | K23: =IF($B23="","",IF($F23=10,"Y","")) -> Y | L23: =IF($B23="","",IF(ISNUMBER(SEARCH("Hardride",$D23)),"Y","")) | M23: Y | N23: ="Event_" & TEXT(A23,"00") -> Event_22
A24: =A23+1 -> 23 | B24: 45907 | C24: 0.4375 | D24: Interclub Hillclimb RFW | F24: 0.88 | G24: Nevill Holt | H24: Y | I24: Y | J24: =IF($B24="","",IF($F24=10,"","Y")) -> Y | K24: =IF($B24="","",IF($F24=10,"Y","")) | L24: =IF($B24="","",IF(ISNUMBER(SEARCH("Hardride",$D24)),"Y","")) | N24: ="Event_" & TEXT(A24,"00") -> Event_23
A25: =A24+1 -> 24 | B25: 45914 | C25: 19:00 | D25: Thorpe Langton 10mile TT | F25: 10 | G25: Thorpe Langton | I25: Y | J25: =IF($B25="","",IF($F25=10,"","Y")) | K25: =IF($B25="","",IF($F25=10,"Y","")) -> Y | L25: =IF($B25="","",IF(ISNUMBER(SEARCH("Hardride",$D25)),"Y","")) | N25: ="Event_" & TEXT(A25,"00") -> Event_24
A26: =A25+1 -> 25 | B26: 45916 | C26: 18:30 | D26: TBA 10mile TT | F26: 10 | G26: TBA | I26: Y | J26: =IF($B26="","",IF($F26=10,"","Y")) | K26: =IF($B26="","",IF($F26=10,"Y","")) -> Y | L26: =IF($B26="","",IF(ISNUMBER(SEARCH("Hardride",$D26)),"Y","")) | N26: ="Event_" & TEXT(A26,"00") -> Event_25 | O26: Y
A27: =A26+1 -> 26 | B27: 45923 | C27: 10:00 | D27: TBA 10mile TT | F27: 10 | G27: TBA | I27: Y | J27: =IF($B27="","",IF($F27=10,"","Y")) | K27: =IF($B27="","",IF($F27=10,"Y","")) -> Y | L27: =IF($B27="","",IF(ISNUMBER(SEARCH("Hardride",$D27)),"Y","")) | N27: ="Event_" & TEXT(A27,"00") -> Event_26 | O27: Y

Sheet Leagues
A1: ClubNumber | B1: ClubMemberName | C1: LeagueDivision
A2: =IF(ISBLANK(B2),"",_xlfn.XLOOKUP(B2,ClubNames,ClubNumbers)) -> 1094 | B2: Andy Poulton | C2: Prem
A3: =IF(ISBLANK(B3),"",_xlfn.XLOOKUP(B3,ClubNames,ClubNumbers)) -> 933 | B3: Ed Grandidge | C3: Prem
A4: =IF(ISBLANK(B4),"",_xlfn.XLOOKUP(B4,ClubNames,ClubNumbers)) -> 1023 | B4: Gary Roberts | C4: Prem
A5: =IF(ISBLANK(B5),"",_xlfn.XLOOKUP(B5,ClubNames,ClubNumbers)) -> 407 | B5: Hans van Nierop | C5: Prem
A6: =IF(ISBLANK(B6),"",_xlfn.XLOOKUP(B6,ClubNames,ClubNumbers)) -> 1144 | B6: Jamie Kershaw | C6: Prem
A7: =IF(ISBLANK(B7),"",_xlfn.XLOOKUP(B7,ClubNames,ClubNumbers)) -> 989 | B7: Jason Williams | C7: Prem
A8: =IF(ISBLANK(B8),"",_xlfn.XLOOKUP(B8,ClubNames,ClubNumbers)) -> 699 | B8: Jonathan Durnin | C8: Prem
A9: =IF(ISBLANK(B9),"",_xlfn.XLOOKUP(B9,ClubNames,ClubNumbers)) -> 1161 | B9: Maciej Suchocki | C9: Prem
A10: =IF(ISBLANK(B10),"",_xlfn.XLOOKUP(B10,ClubNames,ClubNumbers)) -> 35 | B10: Matt Plews | C10: Prem
A11: =IF(ISBLANK(B11),"",_xlfn.XLOOKUP(B11,ClubNames,ClubNumbers)) -> 1055 | B11: Austin Smith | C11: 1
A12: =IF(ISBLANK(B12),"",_xlfn.XLOOKUP(B12,ClubNames,ClubNumbers)) -> 1192 | B12: Dale Norris | C12: 1
A13: =IF(ISBLANK(B13),"",_xlfn.XLOOKUP(B13,ClubNames,ClubNumbers)) -> 1137 | B13: Graham Doe | C13: 1
A14: =IF(ISBLANK(B14),"",_xlfn.XLOOKUP(B14,ClubNames,ClubNumbers)) -> 747 | B14: James Moore | C14: 1
A15: =IF(ISBLANK(B15),"",_xlfn.XLOOKUP(B15,ClubNames,ClubNumbers)) -> 756 | B15: Josh van Nierop | C15: 1
A16: =IF(ISBLANK(B16),"",_xlfn.XLOOKUP(B16,ClubNames,ClubNumbers)) -> 1364 | B16: Laurence Noble | C16: 1
A17: =IF(ISBLANK(B17),"",_xlfn.XLOOKUP(B17,ClubNames,ClubNumbers)) -> 567 | B17: Lawrence Cox | C17: 1
A18: =IF(ISBLANK(B18),"",_xlfn.XLOOKUP(B18,ClubNames,ClubNumbers)) -> 415 | B18: Nik Kershaw | C18: 1
A19: =IF(ISBLANK(B19),"",_xlfn.XLOOKUP(B19,ClubNames,ClubNumbers)) -> 1375 | B19: Tom Spencer | C19: 1
A20: =IF(ISBLANK(B20),"",_xlfn.XLOOKUP(B20,ClubNames,ClubNumbers)) -> 1129 | B20: Doug Tincello | C20: 2
A21: =IF(ISBLANK(B21),"",_xlfn.XLOOKUP(B21,ClubNames,ClubNumbers)) -> 1339 | B21: Jack Shewring | C21: 2
A22: =IF(ISBLANK(B22),"",_xlfn.XLOOKUP(B22,ClubNames,ClubNumbers)) -> 1237 | B22: John Abbott | C22: 2
... A42: =IF(ISBLANK(B42),"",_xlfn.XLOOKUP(B42,ClubNames,ClubNumbers)) -> 1244 | B42: Steven Latham | C42: 4
A43: =IF(ISBLANK(B43),"",_xlfn.XLOOKUP(B43,ClubNames,ClubNumbers)) -> 38 | B43: Phil Rayner | C43: Prem
A44: =IF(ISBLANK(B44),"",_xlfn.XLOOKUP(B44,ClubNames,ClubNumbers)) -> 967 | B44: Daniel McDonnell | C44: 1
A45: =IF(ISBLANK(B45),"",_xlfn.XLOOKUP(B45,ClubNames,ClubNumbers)) -> 1242 | B45: Mike Sirett | C45: 2
A46: =IF(ISBLANK(B46),"",_xlfn.XLOOKUP(B46,ClubNames,ClubNumbers)) -> 1135 | B46: Simon Askham | C46: 2
A47: =IF(ISBLANK(B47),"",_xlfn.XLOOKUP(B47,ClubNames,ClubNumbers)) -> 715 | B47: Steven Coulam | C47: 3
A48: =IF(ISBLANK(B48),"",_xlfn.XLOOKUP(B48,ClubNames,ClubNumbers)) -> 1254 | B48: Paul White | C48: 3
A49: =IF(ISBLANK(B49),"",_xlfn.XLOOKUP(B49,ClubNames,ClubNumbers)) -> 1385 | B49: Miles Marr | C49: 3
A50: =IF(ISBLANK(B50),"",_xlfn.XLOOKUP(B50,ClubNames,ClubNumbers)) -> 7 | B50: Vic Barnett | C50: 4
A51: =IF(ISBLANK(B51),"",_xlfn.XLOOKUP(B51,ClubNames,ClubNumbers))
A52: =IF(ISBLANK(B52),"",_xlfn.XLOOKUP(B52,ClubNames,ClubNumbers))
A53: =IF(ISBLANK(B53),"",_xlfn.XLOOKUP(B53,ClubNames,ClubNumbers))
A54: =IF(ISBLANK(B54),"",_xlfn.XLOOKUP(B54,ClubNames,ClubNumbers))
A55: =IF(ISBLANK(B55),"",_xlfn.XLOOKUP(B55,ClubNames,ClubNumbers))
A56: =IF(ISBLANK(B56),"",_xlfn.XLOOKUP(B56,ClubNames,ClubNumbers))
A57: =IF(ISBLANK(B57),"",_xlfn.XLOOKUP(B57,ClubNames,ClubNumbers))
A58: =IF(ISBLANK(B58),"",_xlfn.XLOOKUP(B58,ClubNames,ClubNumbers))
A59: =IF(ISBLANK(B59),"",_xlfn.XLOOKUP(B59,ClubNames,ClubNumbers))
...

Sheet RoundRobinRiders
A1: Name | B1: Club | C1: Decorated Name | D1: isFemale
A2: Carl Dyson | B2: Aerologic | C2: =IF(ISBLANK(B2), IF(ISBLANK(A2),"",A2), _xlfn.CONCAT(A2," (",B2,")")) -> Carl Dyson (Aerologic) | H2: Derek Lawlor
A3: Tommy Nolan | B3: Ashby ICC | C3: =IF(ISBLANK(B3), IF(ISBLANK(A3),"",A3), _xlfn.CONCAT(A3," (",B3,")")) -> Tommy Nolan (Ashby ICC) | H3: Tyler Dyson
A4: Jayne Mumford (W) | B4: Cov Tri | C4: =IF(ISBLANK(B4), IF(ISBLANK(A4),"",A4), _xlfn.CONCAT(A4," (",B4,")")) -> Jayne Mumford (W) (Cov Tri) | D4: Y | H4: Robert Mitchell
A5: Simon Clarke | B5: Cov Tri | C5: =IF(ISBLANK(B5), IF(ISBLANK(A5),"",A5), _xlfn.CONCAT(A5," (",B5,")")) -> Simon Clarke (Cov Tri)
A6: Andy Thomas | B6: HCRC | C6: =IF(ISBLANK(B6), IF(ISBLANK(A6),"",A6), _xlfn.CONCAT(A6," (",B6,")")) -> Andy Thomas (HCRC)
A7: Colin Parkinson (SWRC) | B7: HCRC | C7: =IF(ISBLANK(B7), IF(ISBLANK(A7),"",A7), _xlfn.CONCAT(A7," (",B7,")")) -> Colin Parkinson (SWRC) (HCRC)
A8: Joe Murray (M I Racing) | B8: HCRC | C8: =IF(ISBLANK(B8), IF(ISBLANK(A8),"",A8), _xlfn.CONCAT(A8," (",B8,")")) -> Joe Murray (M I Racing) (HCRC)
A9: Mick Wills (M I Racing) | B9: HCRC | C9: =IF(ISBLANK(B9), IF(ISBLANK(A9),"",A9), _xlfn.CONCAT(A9," (",B9,")")) -> Mick Wills (M I Racing) (HCRC)
A10: Andy King | B10: KCC | C10: =IF(ISBLANK(B10), IF(ISBLANK(A10),"",A10), _xlfn.CONCAT(A10," (",B10,")")) -> Andy King (KCC)
A11: Evan Collett Jnr | B11: KCC | C11: =IF(ISBLANK(B11), IF(ISBLANK(A11),"",A11), _xlfn.CONCAT(A11," (",B11,")")) -> Evan Collett Jnr (KCC)
A12: Josh Brown | B12: KCC | C12: =IF(ISBLANK(B12), IF(ISBLANK(A12),"",A12), _xlfn.CONCAT(A12," (",B12,")")) -> Josh Brown (KCC)
A13: Harriet Hughes | B13: LFCC | C13: =IF(ISBLANK(B13), IF(ISBLANK(A13),"",A13), _xlfn.CONCAT(A13," (",B13,")")) -> Harriet Hughes (LFCC) | D13: Y
A14: Mat Mabe | B14: LFCC | C14: =IF(ISBLANK(B14), IF(ISBLANK(A14),"",A14), _xlfn.CONCAT(A14," (",B14,")")) -> Mat Mabe (LFCC)
A15: Matt Finch | B15: LFCC | C15: =IF(ISBLANK(B15), IF(ISBLANK(A15),"",A15), _xlfn.CONCAT(A15," (",B15,")")) -> Matt Finch (LFCC)
A16: Morris Mabe | B16: LFCC | C16: =IF(ISBLANK(B16), IF(ISBLANK(A16),"",A16), _xlfn.CONCAT(A16," (",B16,")")) -> Morris Mabe (LFCC)
A17: Sam Nettel | B17: LFCC | C17: =IF(ISBLANK(B17), IF(ISBLANK(A17),"",A17), _xlfn.CONCAT(A17," (",B17,")")) -> Sam Nettel (LFCC)
A18: Talles Medevives | B18: LFCC | C18: =IF(ISBLANK(B18), IF(ISBLANK(A18),"",A18), _xlfn.CONCAT(A18," (",B18,")")) -> Talles Medevives (LFCC)
A19: Dean Tacey | B19: LRC | C19: =IF(ISBLANK(B19), IF(ISBLANK(A19),"",A19), _xlfn.CONCAT(A19," (",B19,")")) -> Dean Tacey (LRC)
A20: Chris Booth | B20: MOCC | C20: =IF(ISBLANK(B20), IF(ISBLANK(A20),"",A20), _xlfn.CONCAT(A20," (",B20,")")) -> Chris Booth (MOCC)
A21: David Cooper | B21: MOCC | C21: =IF(ISBLANK(B21), IF(ISBLANK(A21),"",A21), _xlfn.CONCAT(A21," (",B21,")")) -> David Cooper (MOCC)
A22: Jamie Haines | B22: MOCC | C22: =IF(ISBLANK(B22), IF(ISBLANK(A22),"",A22), _xlfn.CONCAT(A22," (",B22,")")) -> Jamie Haines (MOCC)
A23: Laura Ayers (W) | B23: MOCC | C23: =IF(ISBLANK(B23), IF(ISBLANK(A23),"",A23), _xlfn.CONCAT(A23," (",B23,")")) -> Laura Ayers (W) (MOCC) | D23: Y
A24: Ed Tarelli | B24: Race Hub | C24: =IF(ISBLANK(B24), IF(ISBLANK(A24),"",A24), _xlfn.CONCAT(A24," (",B24,")")) -> Ed Tarelli (Race Hub)
A25: Lewis Cooper | B25: RAF Tri | C25: =IF(ISBLANK(B25), IF(ISBLANK(A25),"",A25), _xlfn.CONCAT(A25," (",B25,")")) -> Lewis Cooper (RAF Tri)
A26: Alex Whitmore | B26: Ratae | C26: =IF(ISBLANK(B26), IF(ISBLANK(A26),"",A26), _xlfn.CONCAT(A26," (",B26,")")) -> Alex Whitmore (Ratae)
A27: Brian Lincoln | B27: Ratae | C27: =IF(ISBLANK(B27), IF(ISBLANK(A27),"",A27), _xlfn.CONCAT(A27," (",B27,")")) -> Brian Lincoln (Ratae)
A28: Chris Bonsor | B28: Ratae | C28: =IF(ISBLANK(B28), IF(ISBLANK(A28),"",A28), _xlfn.CONCAT(A28," (",B28,")")) -> Chris Bonsor (Ratae)
A29: Chris Spray | B29: Ratae | C29: =IF(ISBLANK(B29), IF(ISBLANK(A29),"",A29), _xlfn.CONCAT(A29," (",B29,")")) -> Chris Spray (Ratae)
A30: Debbie Cooper | B30: Ratae | C30: =IF(ISBLANK(B30), IF(ISBLANK(A30),"",A30), _xlfn.CONCAT(A30," (",B30,")")) -> Debbie Cooper (Ratae) | D30: Y
A31: Ed Watson | B31: Ratae | C31: =IF(ISBLANK(B31), IF(ISBLANK(A31),"",A31), _xlfn.CONCAT(A31," (",B31,")")) -> Ed Watson (Ratae)
A32: Jonathon Clarke | B32: Ratae | C32: =IF(ISBLANK(B32), IF(ISBLANK(A32),"",A32), _xlfn.CONCAT(A32," (",B32,")")) -> Jonathon Clarke (Ratae)
A33: Lucy Sturgess | B33: Ratae | C33: =IF(ISBLANK(B33), IF(ISBLANK(A33),"",A33), _xlfn.CONCAT(A33," (",B33,")")) -> Lucy Sturgess (Ratae) | D33: Y
A34: Mark Marmoy | B34: Ratae | C34: =IF(ISBLANK(B34), IF(ISBLANK(A34),"",A34), _xlfn.CONCAT(A34," (",B34,")")) -> Mark Marmoy (Ratae)
A35: Mark Newton | B35: Ratae | C35: =IF(ISBLANK(B35), IF(ISBLANK(A35),"",A35), _xlfn.CONCAT(A35," (",B35,")")) -> Mark Newton (Ratae)
A36: Marshall Briggs | B36: Ratae | C36: =IF(ISBLANK(B36), IF(ISBLANK(A36),"",A36), _xlfn.CONCAT(A36," (",B36,")")) -> Marshall Briggs (Ratae)
A37: Paul Eden | B37: Ratae | C37: =IF(ISBLANK(B37), IF(ISBLANK(A37),"",A37), _xlfn.CONCAT(A37," (",B37,")")) -> Paul Eden (Ratae)
A38: Sadie Murphy | B38: Ratae | C38: =IF(ISBLANK(B38), IF(ISBLANK(A38),"",A38), _xlfn.CONCAT(A38," (",B38,")")) -> Sadie Murphy (Ratae) | D38: Y
A39: Steve Pearce | B39: Ratae | C39: =IF(ISBLANK(B39), IF(ISBLANK(A39),"",A39), _xlfn.CONCAT(A39," (",B39,")")) -> Steve Pearce (Ratae)
A40: Adam Wells | B40: RFW | C40: =IF(ISBLANK(B40), IF(ISBLANK(A40),"",A40), _xlfn.CONCAT(A40," (",B40,")")) -> Adam Wells (RFW)
...

Sheet Event_01
A1: Number/Name | B1: H | C1: M | D1: S | E1: Roadbike? | F1: DNS/DNF/DQ | G1: Name | H1: Actual Time | I1: Guest or Not Renewed | J1: Raw Name
A2: =IF(J2="","",_xlfn.XLOOKUP(J2,ClubNames,ClubNumbers,_xlfn.XLOOKUP(J2,RoundRobinRiderNames,RoundRobinRiderDecoratedNames,J2))) -> 1144 | B2: 0 | C2: 24 | D2: 18 | E2: r | G2: =IF($A2="","",IF($I2="X",A2,CONCATENATE(VLOOKUP(A2,Competitors!$A$2:$I$650,3, FALSE)," ",VLOOKUP(A2,Competitors!$A$2:$I$650,2,FALSE)))) -> Jamie Kershaw | H2: =IF(LEFT($E2,1)="D",UPPER($E2),(B2*3600+C2*60+D2)/86400) -> 0.016875 | I2: =IF(OR(A2="",ISNUMBER(A2)),"","X") | J2: Jamie Kershaw
A3: =IF(J3="","",_xlfn.XLOOKUP(J3,ClubNames,ClubNumbers,_xlfn.XLOOKUP(J3,RoundRobinRiderNames,RoundRobinRiderDecoratedNames,J3))) -> 407 | B3: 0 | C3: 24 | D3: 53 | G3: =IF($A3="","",IF($I3="X",A3,CONCATENATE(VLOOKUP(A3,Competitors!$A$2:$I$650,3, FALSE)," ",VLOOKUP(A3,Competitors!$A$2:$I$650,2,FALSE)))) -> Hans van Nierop | H3: =IF(LEFT($E3,1)="D",UPPER($E3),(B3*3600+C3*60+D3)/86400) -> 0.017280093 | I3: =IF(OR(A3="",ISNUMBER(A3)),"","X") | J3: Hans van Nierop
A4: =IF(J4="","",_xlfn.XLOOKUP(J4,ClubNames,ClubNumbers,_xlfn.XLOOKUP(J4,RoundRobinRiderNames,RoundRobinRiderDecoratedNames,J4))) -> 1364 | B4: 0 | C4: 26 | D4: 1 | G4: =IF($A4="","",IF($I4="X",A4,CONCATENATE(VLOOKUP(A4,Competitors!$A$2:$I$650,3, FALSE)," ",VLOOKUP(A4,Competitors!$A$2:$I$650,2,FALSE)))) -> Laurence Noble | H4: =IF(LEFT($E4,1)="D",UPPER($E4),(B4*3600+C4*60+D4)/86400) -> 0.01806713 | I4: =IF(OR(A4="",ISNUMBER(A4)),"","X") | J4: Laurence Noble
A5: =IF(J5="","",_xlfn.XLOOKUP(J5,ClubNames,ClubNumbers,_xlfn.XLOOKUP(J5,RoundRobinRiderNames,RoundRobinRiderDecoratedNames,J5))) -> 35 | B5: 0 | C5: 26 | D5: 15 | G5: =IF($A5="","",IF($I5="X",A5,CONCATENATE(VLOOKUP(A5,Competitors!$A$2:$I$650,3, FALSE)," ",VLOOKUP(A5,Competitors!$A$2:$I$650,2,FALSE)))) -> Matt Plews | H5: =IF(LEFT($E5,1)="D",UPPER($E5),(B5*3600+C5*60+D5)/86400) -> 0.018229167 | I5: =IF(OR(A5="",ISNUMBER(A5)),"","X") | J5: Matt Plews
A6: =IF(J6="","",_xlfn.XLOOKUP(J6,ClubNames,ClubNumbers,_xlfn.XLOOKUP(J6,RoundRobinRiderNames,RoundRobinRiderDecoratedNames,J6))) -> 1152 | B6: 0 | C6: 26 | D6: 17 | E6: r | G6: =IF($A6="","",IF($I6="X",A6,CONCATENATE(VLOOKUP(A6,Competitors!$A$2:$I$650,3, FALSE)," ",VLOOKUP(A6,Competitors!$A$2:$I$650,2,FALSE)))) -> Ruby Isaac | H6: =IF(LEFT($E6,1)="D",UPPER($E6),(B6*3600+C6*60+D6)/86400) -> 0.018252315 | I6: =IF(OR(A6="",ISNUMBER(A6)),"","X") | J6: Ruby Isaac
A7: =IF(J7="","",_xlfn.XLOOKUP(J7,ClubNames,ClubNumbers,_xlfn.XLOOKUP(J7,RoundRobinRiderNames,RoundRobinRiderDecoratedNames,J7))) -> 415 | B7: 0 | C7: 26 | D7: 29 | E7: r | G7: =IF($A7="","",IF($I7="X",A7,CONCATENATE(VLOOKUP(A7,Competitors!$A$2:$I$650,3, FALSE)," ",VLOOKUP(A7,Competitors!$A$2:$I$650,2,FALSE)))) -> Nik Kershaw | H7: =IF(LEFT($E7,1)="D",UPPER($E7),(B7*3600+C7*60+D7)/86400) -> 0.018391204 | I7: =IF(OR(A7="",ISNUMBER(A7)),"","X") | J7: Nik Kershaw
A8: =IF(J8="","",_xlfn.XLOOKUP(J8,ClubNames,ClubNumbers,_xlfn.XLOOKUP(J8,RoundRobinRiderNames,RoundRobinRiderDecoratedNames,J8))) -> 1192 | B8: 0 | C8: 26 | D8: 44 | G8: =IF($A8="","",IF($I8="X",A8,CONCATENATE(VLOOKUP(A8,Competitors!$A$2:$I$650,3, FALSE)," ",VLOOKUP(A8,Competitors!$A$2:$I$650,2,FALSE)))) -> Dale Norris | H8: =IF(LEFT($E8,1)="D",UPPER($E8),(B8*3600+C8*60+D8)/86400) -> 0.018564815 | I8: =IF(OR(A8="",ISNUMBER(A8)),"","X") | J8: Dale Norris
A9: =IF(J9="","",_xlfn.XLOOKUP(J9,ClubNames,ClubNumbers,_xlfn.XLOOKUP(J9,RoundRobinRiderNames,RoundRobinRiderDecoratedNames,J9))) -> 1055 | B9: 0 | C9: 26 | D9: 46 | E9: r | G9: =IF($A9="","",IF($I9="X",A9,CONCATENATE(VLOOKUP(A9,Competitors!$A$2:$I$650,3, FALSE)," ",VLOOKUP(A9,Competitors!$A$2:$I$650,2,FALSE)))) -> Austin Smith | H9: =IF(LEFT($E9,1)="D",UPPER($E9),(B9*3600+C9*60+D9)/86400) -> 0.018587963 | I9: =IF(OR(A9="",ISNUMBER(A9)),"","X") | J9: Austin Smith
A10: =IF(J10="","",_xlfn.XLOOKUP(J10,ClubNames,ClubNumbers,_xlfn.XLOOKUP(J10,RoundRobinRiderNames,RoundRobinRiderDecoratedNames,J10))) -> 1094 | B10: 0 | C10: 26 | D10: 55 | G10: =IF($A10="","",IF($I10="X",A10,CONCATENATE(VLOOKUP(A10,Competitors!$A$2:$I$650,3, FALSE)," ",VLOOKUP(A10,Competitors!$A$2:$I$650,2,FALSE)))) -> Andy Poulton | H10: =IF(LEFT($E10,1)="D",UPPER($E10),(B10*3600+C10*60+D10)/86400) -> 0.01869213 | I10: =IF(OR(A10="",ISNUMBER(A10)),"","X") | J10: Andy Poulton
A11: =IF(J11="","",_xlfn.XLOOKUP(J11,ClubNames,ClubNumbers,_xlfn.XLOOKUP(J11,RoundRobinRiderNames,RoundRobinRiderDecoratedNames,J11))) -> 699 | B11: 0 | C11: 27 | D11: 21 | E11: r | G11: =IF($A11="","",IF($I11="X",A11,CONCATENATE(VLOOKUP(A11,Competitors!$A$2:$I$650,3, FALSE)," ",VLOOKUP(A11,Competitors!$A$2:$I$650,2,FALSE)))) -> Jonathan Durnin | H11: =IF(LEFT($E11,1)="D",UPPER($E11),(B11*3600+C11*60+D11)/86400) -> 0.018993056 | I11: =IF(OR(A11="",ISNUMBER(A11)),"","X") | J11: Jonathan Durnin
A12: =IF(J12="","",_xlfn.XLOOKUP(J12,ClubNames,ClubNumbers,_xlfn.XLOOKUP(J12,RoundRobinRiderNames,RoundRobinRiderDecoratedNames,J12))) -> 1237 | B12: 0 | C12: 27 | D12: 23 | E12: r | G12: =IF($A12="","",IF($I12="X",A12,CONCATENATE(VLOOKUP(A12,Competitors!$A$2:$I$650,3, FALSE)," ",VLOOKUP(A12,Competitors!$A$2:$I$650,2,FALSE)))) -> John Abbott | H12: =IF(LEFT($E12,1)="D",UPPER($E12),(B12*3600+C12*60+D12)/86400) -> 0.019016204 | I12: =IF(OR(A12="",ISNUMBER(A12)),"","X") | J12: John Abbott
A13: Graham Doe | B13: 0 | C13: 27 | D13: 30 | G13: =IF($A13="","",IF($I13="X",A13,CONCATENATE(VLOOKUP(A13,Competitors!$A$2:$I$650,3, FALSE)," ",VLOOKUP(A13,Competitors!$A$2:$I$650,2,FALSE)))) -> Graham Doe | H13: =IF(LEFT($E13,1)="D",UPPER($E13),(B13*3600+C13*60+D13)/86400) -> 0.019097222 | I13: =IF(OR(A13="",ISNUMBER(A13)),"","X") -> X | J13: Graham Doe
A14: =IF(J14="","",_xlfn.XLOOKUP(J14,ClubNames,ClubNumbers,_xlfn.XLOOKUP(J14,RoundRobinRiderNames,RoundRobinRiderDecoratedNames,J14))) -> 468 | B14: 0 | C14: 27 | D14: 35 | E14: r | G14: =IF($A14="","",IF($I14="X",A14,CONCATENATE(VLOOKUP(A14,Competitors!$A$2:$I$650,3, FALSE)," ",VLOOKUP(A14,Competitors!$A$2:$I$650,2,FALSE)))) -> Mike Smith | H14: =IF(LEFT($E14,1)="D",UPPER($E14),(B14*3600+C14*60+D14)/86400) -> 0.019155093 | I14: =IF(OR(A14="",ISNUMBER(A14)),"","X") | J14: Mike Smith
A15: =IF(J15="","",_xlfn.XLOOKUP(J15,ClubNames,ClubNumbers,_xlfn.XLOOKUP(J15,RoundRobinRiderNames,RoundRobinRiderDecoratedNames,J15))) -> Ed Watson (Ratae) | B15: 0 | C15: 28 | D15: 42 | E15: r | G15: =IF($A15="","",IF($I15="X",A15,CONCATENATE(VLOOKUP(A15,Competitors!$A$2:$I$650,3, FALSE)," ",VLOOKUP(A15,Competitors!$A$2:$I$650,2,FALSE)))) -> Ed Watson (Ratae) | H15: =IF(LEFT($E15,1)="D",UPPER($E15),(B15*3600+C15*60+D15)/86400) -> 0.019930556 | I15: =IF(OR(A15="",ISNUMBER(A15)),"","X") -> X | J15: Ed Watson
A16: =IF(J16="","",_xlfn.XLOOKUP(J16,ClubNames,ClubNumbers,_xlfn.XLOOKUP(J16,RoundRobinRiderNames,RoundRobinRiderDecoratedNames,J16))) -> 846 | B16: 0 | C16: 28 | D16: 45 | G16: =IF($A16="","",IF($I16="X",A16,CONCATENATE(VLOOKUP(A16,Competitors!$A$2:$I$650,3, FALSE)," ",VLOOKUP(A16,Competitors!$A$2:$I$650,2,FALSE)))) -> Roger Kockelbergh | H16: =IF(LEFT($E16,1)="D",UPPER($E16),(B16*3600+C16*60+D16)/86400) -> 0.019965278 | I16: =IF(OR(A16="",ISNUMBER(A16)),"","X") | J16: Roger Kockelbergh
A17: =IF(J17="","",_xlfn.XLOOKUP(J17,ClubNames,ClubNumbers,_xlfn.XLOOKUP(J17,RoundRobinRiderNames,RoundRobinRiderDecoratedNames,J17))) -> 203 | B17: 0 | C17: 29 | D17: 28 | G17: =IF($A17="","",IF($I17="X",A17,CONCATENATE(VLOOKUP(A17,Competitors!$A$2:$I$650,3, FALSE)," ",VLOOKUP(A17,Competitors!$A$2:$I$650,2,FALSE)))) -> Adrian Killworth | H17: =IF(LEFT($E17,1)="D",UPPER($E17),(B17*3600+C17*60+D17)/86400) -> 0.020462963 | I17: =IF(OR(A17="",ISNUMBER(A17)),"","X") | J17: Adrian Killworth
A18: =IF(J18="","",_xlfn.XLOOKUP(J18,ClubNames,ClubNumbers,_xlfn.XLOOKUP(J18,RoundRobinRiderNames,RoundRobinRiderDecoratedNames,J18))) -> 532 | B18: 0 | C18: 29 | D18: 30 | E18: r | G18: =IF($A18="","",IF($I18="X",A18,CONCATENATE(VLOOKUP(A18,Competitors!$A$2:$I$650,3, FALSE)," ",VLOOKUP(A18,Competitors!$A$2:$I$650,2,FALSE)))) -> Kevin Mills | H18: =IF(LEFT($E18,1)="D",UPPER($E18),(B18*3600+C18*60+D18)/86400) -> 0.020486111 | I18: =IF(OR(A18="",ISNUMBER(A18)),"","X") | J18: Kevin Mills
A19: =IF(J19="","",_xlfn.XLOOKUP(J19,ClubNames,ClubNumbers,_xlfn.XLOOKUP(J19,RoundRobinRiderNames,RoundRobinRiderDecoratedNames,J19))) -> 704 | B19: 0 | C19: 30 | D19: 25 | E19: r | G19: =IF($A19="","",IF($I19="X",A19,CONCATENATE(VLOOKUP(A19,Competitors!$A$2:$I$650,3, FALSE)," ",VLOOKUP(A19,Competitors!$A$2:$I$650,2,FALSE)))) -> Chris Dainty | H19: =IF(LEFT($E19,1)="D",UPPER($E19),(B19*3600+C19*60+D19)/86400) -> 0.021122685 | I19: =IF(OR(A19="",ISNUMBER(A19)),"","X") | J19: Chris Dainty
A20: =IF(J20="","",_xlfn.XLOOKUP(J20,ClubNames,ClubNumbers,_xlfn.XLOOKUP(J20,RoundRobinRiderNames,RoundRobinRiderDecoratedNames,J20))) -> 23 | B20: 0 | C20: 30 | D20: 30 | G20: =IF($A20="","",IF($I20="X",A20,CONCATENATE(VLOOKUP(A20,Competitors!$A$2:$I$650,3, FALSE)," ",VLOOKUP(A20,Competitors!$A$2:$I$650,2,FALSE)))) -> Chris Hyde | H20: =IF(LEFT($E20,1)="D",UPPER($E20),(B20*3600+C20*60+D20)/86400) -> 0.021180556 | I20: =IF(OR(A20="",ISNUMBER(A20)),"","X") | J20: Chris Hyde
A21: =IF(J21="","",_xlfn.XLOOKUP(J21,ClubNames,ClubNumbers,_xlfn.XLOOKUP(J21,RoundRobinRiderNames,RoundRobinRiderDecoratedNames,J21))) -> 1112 | B21: 0 | C21: 30 | D21: 50 | G21: =IF($A21="","",IF($I21="X",A21,CONCATENATE(VLOOKUP(A21,Competitors!$A$2:$I$650,3, FALSE)," ",VLOOKUP(A21,Competitors!$A$2:$I$650,2,FALSE)))) -> Gary Ashwell | H21: =IF(LEFT($E21,1)="D",UPPER($E21),(B21*3600+C21*60+D21)/86400) -> 0.021412037 | I21: =IF(OR(A21="",ISNUMBER(A21)),"","X") | J21: Gary Ashwell
A22: =IF(J22="","",_xlfn.XLOOKUP(J22,ClubNames,ClubNumbers,_xlfn.XLOOKUP(J22,RoundRobinRiderNames,RoundRobinRiderDecoratedNames,J22))) -> 616 | B22: 0 | C22: 31 | D22: 27 | G22: =IF($A22="","",IF($I22="X",A22,CONCATENATE(VLOOKUP(A22,Competitors!$A$2:$I$650,3, FALSE)," ",VLOOKUP(A22,Competitors!$A$2:$I$650,2,FALSE)))) -> Simon Ward | H22: =IF(LEFT($E22,1)="D",UPPER($E22),(B22*3600+C22*60+D22)/86400) -> 0.021840278 | I22: =IF(OR(A22="",ISNUMBER(A22)),"","X") | J22: Simon Ward
A23: =IF(J23="","",_xlfn.XLOOKUP(J23,ClubNames,ClubNumbers,_xlfn.XLOOKUP(J23,RoundRobinRiderNames,RoundRobinRiderDecoratedNames,J23))) | G23: =IF($A23="","",IF($I23="X",A23,CONCATENATE(VLOOKUP(A23,Competitors!$A$2:$I$650,3, FALSE)," ",VLOOKUP(A23,Competitors!$A$2:$I$650,2,FALSE)))) | H23: =IF(LEFT($E23,1)="D",UPPER($E23),(B23*3600+C23*60+D23)/86400) -> 0 | I23: =IF(OR(A23="",ISNUMBER(A23)),"","X")
A24: =IF(J24="","",_xlfn.XLOOKUP(J24,ClubNames,ClubNumbers,_xlfn.XLOOKUP(J24,RoundRobinRiderNames,RoundRobinRiderDecoratedNames,J24))) | G24: =IF($A24="","",IF($I24="X",A24,CONCATENATE(VLOOKUP(A24,Competitors!$A$2:$I$650,3, FALSE)," ",VLOOKUP(A24,Competitors!$A$2:$I$650,2,FALSE)))) | H24: =IF(LEFT($E24,1)="D",UPPER($E24),(B24*3600+C24*60+D24)/86400) -> 0 | I24: =IF(OR(A24="",ISNUMBER(A24)),"","X")
A25: =IF(J25="","",_xlfn.XLOOKUP(J25,ClubNames,ClubNumbers,_xlfn.XLOOKUP(J25,RoundRobinRiderNames,RoundRobinRiderDecoratedNames,J25))) | G25: =IF($A25="","",IF($I25="X",A25,CONCATENATE(VLOOKUP(A25,Competitors!$A$2:$I$650,3, FALSE)," ",VLOOKUP(A25,Competitors!$A$2:$I$650,2,FALSE)))) | H25: =IF(LEFT($E25,1)="D",UPPER($E25),(B25*3600+C25*60+D25)/86400) -> 0 | I25: =IF(OR(A25="",ISNUMBER(A25)),"","X")
A26: =IF(J26="","",_xlfn.XLOOKUP(J26,ClubNames,ClubNumbers,_xlfn.XLOOKUP(J26,RoundRobinRiderNames,RoundRobinRiderDecoratedNames,J26))) | G26: =IF($A26="","",IF($I26="X",A26,CONCATENATE(VLOOKUP(A26,Competitors!$A$2:$I$650,3, FALSE)," ",VLOOKUP(A26,Competitors!$A$2:$I$650,2,FALSE)))) | H26: =IF(LEFT($E26,1)="D",UPPER($E26),(B26*3600+C26*60+D26)/86400) -> 0 | I26: =IF(OR(A26="",ISNUMBER(A26)),"","X")
A27: =IF(J27="","",_xlfn.XLOOKUP(J27,ClubNames,ClubNumbers,_xlfn.XLOOKUP(J27,RoundRobinRiderNames,RoundRobinRiderDecoratedNames,J27))) | G27: =IF($A27="","",IF($I27="X",A27,CONCATENATE(VLOOKUP(A27,Competitors!$A$2:$I$650,3, FALSE)," ",VLOOKUP(A27,Competitors!$A$2:$I$650,2,FALSE)))) | H27: =IF(LEFT($E27,1)="D",UPPER($E27),(B27*3600+C27*60+D27)/86400) -> 0 | I27: =IF(OR(A27="",ISNUMBER(A27)),"","X")
A28: =IF(J28="","",_xlfn.XLOOKUP(J28,ClubNames,ClubNumbers,_xlfn.XLOOKUP(J28,RoundRobinRiderNames,RoundRobinRiderDecoratedNames,J28))) | G28: =IF($A28="","",IF($I28="X",A28,CONCATENATE(VLOOKUP(A28,Competitors!$A$2:$I$650,3, FALSE)," ",VLOOKUP(A28,Competitors!$A$2:$I$650,2,FALSE)))) | H28: =IF(LEFT($E28,1)="D",UPPER($E28),(B28*3600+C28*60+D28)/86400) -> 0 | I28: =IF(OR(A28="",ISNUMBER(A28)),"","X")
A29: =IF(J29="","",_xlfn.XLOOKUP(J29,ClubNames,ClubNumbers,_xlfn.XLOOKUP(J29,RoundRobinRiderNames,RoundRobinRiderDecoratedNames,J29))) | G29: =IF($A29="","",IF($I29="X",A29,CONCATENATE(VLOOKUP(A29,Competitors!$A$2:$I$650,3, FALSE)," ",VLOOKUP(A29,Competitors!$A$2:$I$650,2,FALSE)))) | H29: =IF(LEFT($E29,1)="D",UPPER($E29),(B29*3600+C29*60+D29)/86400) -> 0 | I29: =IF(OR(A29="",ISNUMBER(A29)),"","X")
A30: =IF(J30="","",_xlfn.XLOOKUP(J30,ClubNames,ClubNumbers,_xlfn.XLOOKUP(J30,RoundRobinRiderNames,RoundRobinRiderDecoratedNames,J30))) | G30: =IF($A30="","",IF($I30="X",A30,CONCATENATE(VLOOKUP(A30,Competitors!$A$2:$I$650,3, FALSE)," ",VLOOKUP(A30,Competitors!$A$2:$I$650,2,FALSE)))) | H30: =IF(LEFT($E30,1)="D",UPPER($E30),(B30*3600+C30*60+D30)/86400) -> 0 | I30: =IF(OR(A30="",ISNUMBER(A30)),"","X")
A31: =IF(J31="","",_xlfn.XLOOKUP(J31,ClubNames,ClubNumbers,_xlfn.XLOOKUP(J31,RoundRobinRiderNames,RoundRobinRiderDecoratedNames,J31))) | G31: =IF($A31="","",IF($I31="X",A31,CONCATENATE(VLOOKUP(A31,Competitors!$A$2:$I$650,3, FALSE)," ",VLOOKUP(A31,Competitors!$A$2:$I$650,2,FALSE)))) | H31: =IF(LEFT($E31,1)="D",UPPER($E31),(B31*3600+C31*60+D31)/86400) -> 0 | I31: =IF(OR(A31="",ISNUMBER(A31)),"","X")
A32: =IF(J32="","",_xlfn.XLOOKUP(J32,ClubNames,ClubNumbers,_xlfn.XLOOKUP(J32,RoundRobinRiderNames,RoundRobinRiderDecoratedNames,J32))) | G32: =IF($A32="","",IF($I32="X",A32,CONCATENATE(VLOOKUP(A32,Competitors!$A$2:$I$650,3, FALSE)," ",VLOOKUP(A32,Competitors!$A$2:$I$650,2,FALSE)))) | H32: =IF(LEFT($E32,1)="D",UPPER($E32),(B32*3600+C32*60+D32)/86400) -> 0 | I32: =IF(OR(A32="",ISNUMBER(A32)),"","X")
A33: =IF(J33="","",_xlfn.XLOOKUP(J33,ClubNames,ClubNumbers,_xlfn.XLOOKUP(J33,RoundRobinRiderNames,RoundRobinRiderDecoratedNames,J33))) | G33: =IF($A33="","",IF($I33="X",A33,CONCATENATE(VLOOKUP(A33,Competitors!$A$2:$I$650,3, FALSE)," ",VLOOKUP(A33,Competitors!$A$2:$I$650,2,FALSE)))) | H33: =IF(LEFT($E33,1)="D",UPPER($E33),(B33*3600+C33*60+D33)/86400) -> 0 | I33: =IF(OR(A33="",ISNUMBER(A33)),"","X")
A34: =IF(J34="","",_xlfn.XLOOKUP(J34,ClubNames,ClubNumbers,_xlfn.XLOOKUP(J34,RoundRobinRiderNames,RoundRobinRiderDecoratedNames,J34))) | G34: =IF($A34="","",IF($I34="X",A34,CONCATENATE(VLOOKUP(A34,Competitors!$A$2:$I$650,3, FALSE)," ",VLOOKUP(A34,Competitors!$A$2:$I$650,2,FALSE)))) | H34: =IF(LEFT($E34,1)="D",UPPER($E34),(B34*3600+C34*60+D34)/86400) -> 0 | I34: =IF(OR(A34="",ISNUMBER(A34)),"","X")
... A101: =IF(J101="","",_xlfn.XLOOKUP(J101,ClubNames,ClubNumbers,_xlfn.XLOOKUP(J101,RoundRobinRiderNames,RoundRobinRiderDecoratedNames,J101))) | G101: =IF($A101="","",IF($I101="X",A101,CONCATENATE(VLOOKUP(A101,Competitors!$A$2:$I$650,3, FALSE)," ",VLOOKUP(A101,Competitors!$A$2:$I$650,2,FALSE)))) | H101: =IF(LEFT($E101,1)="D",UPPER($E101),(B101*3600+C101*60+D101)/86400) -> 0 | I101: =IF(OR(A101="",ISNUMBER(A101)),"","X")
A103: SheetName: | B103: {=MID(CELL("filename",A1),FIND("]",CELL("filename",A1))+1,255)} -> #VALUE!
A104: IsHillClimb? | B104: =_xlfn.XLOOKUP(B103,Calendar!N:N,Calendar!H:H,"Event is not in calendar") -> #VALUE!

Sheet Event_02
A1: Number/Name | B1: H | C1: M | D1: S | E1: Roadbike? | F1: DNS/DNF/DQ | G1: Name | H1: Actual Time | I1: Guest or Not Renewed | J1: Raw Name
A2: =IF(J2="","",_xlfn.XLOOKUP(J2,ClubNames,ClubNumbers,_xlfn.XLOOKUP(J2,RoundRobinRiderNames,RoundRobinRiderDecoratedNames,J2))) -> Paul Pardoe | B2: 0 | C2: 22 | D2: 15 | G2: =IF($A2="","",IF($I2="X",A2,CONCATENATE(VLOOKUP(A2,Competitors!$A$2:$I$650,3, FALSE)," ",VLOOKUP(A2,Competitors!$A$2:$I$650,2,FALSE)))) -> Paul Pardoe | H2: =IF(LEFT($E2,1)="D",UPPER($E2),(B2*3600+C2*60+D2)/86400) -> 0.015451389 | I2: =IF(OR(A2="",ISNUMBER(A2)),"","X") -> X | J2: Paul Pardoe
A3: =IF(J3="","",_xlfn.XLOOKUP(J3,ClubNames,ClubNumbers,_xlfn.XLOOKUP(J3,RoundRobinRiderNames,RoundRobinRiderDecoratedNames,J3))) -> George Fox | B3: 0 | C3: 22 | D3: 20 | G3: =IF($A3="","",IF($I3="X",A3,CONCATENATE(VLOOKUP(A3,Competitors!$A$2:$I$650,3, FALSE)," ",VLOOKUP(A3,Competitors!$A$2:$I$650,2,FALSE)))) -> George Fox | H3: =IF(LEFT($E3,1)="D",UPPER($E3),(B3*3600+C3*60+D3)/86400) -> 0.015509259 | I3: =IF(OR(A3="",ISNUMBER(A3)),"","X") -> X | J3: George Fox
A4: =IF(J4="","",_xlfn.XLOOKUP(J4,ClubNames,ClubNumbers,_xlfn.XLOOKUP(J4,RoundRobinRiderNames,RoundRobinRiderDecoratedNames,J4))) -> Jamie Murray | B4: 0 | C4: 23 | D4: 15 | G4: =IF($A4="","",IF($I4="X",A4,CONCATENATE(VLOOKUP(A4,Competitors!$A$2:$I$650,3, FALSE)," ",VLOOKUP(A4,Competitors!$A$2:$I$650,2,FALSE)))) -> Jamie Murray | H4: =IF(LEFT($E4,1)="D",UPPER($E4),(B4*3600+C4*60+D4)/86400) -> 0.016145833 | I4: =IF(OR(A4="",ISNUMBER(A4)),"","X") -> X | J4: Jamie Murray
A5: =IF(J5="","",_xlfn.XLOOKUP(J5,ClubNames,ClubNumbers,_xlfn.XLOOKUP(J5,RoundRobinRiderNames,RoundRobinRiderDecoratedNames,J5))) -> Oscar Smith | B5: 0 | C5: 23 | D5: 43 | E5: r | G5: =IF($A5="","",IF($I5="X",A5,CONCATENATE(VLOOKUP(A5,Competitors!$A$2:$I$650,3, FALSE)," ",VLOOKUP(A5,Competitors!$A$2:$I$650,2,FALSE)))) -> Oscar Smith | H5: =IF(LEFT($E5,1)="D",UPPER($E5),(B5*3600+C5*60+D5)/86400) -> 0.016469907 | I5: =IF(OR(A5="",ISNUMBER(A5)),"","X") -> X | J5: Oscar Smith
A6: =IF(J6="","",_xlfn.XLOOKUP(J6,ClubNames,ClubNumbers,_xlfn.XLOOKUP(J6,RoundRobinRiderNames,RoundRobinRiderDecoratedNames,J6))) -> Jack Eastman-Nye | B6: 0 | C6: 23 | D6: 46 | G6: =IF($A6="","",IF($I6="X",A6,CONCATENATE(VLOOKUP(A6,Competitors!$A$2:$I$650,3, FALSE)," ",VLOOKUP(A6,Competitors!$A$2:$I$650,2,FALSE)))) -> Jack Eastman-Nye | H6: =IF(LEFT($E6,1)="D",UPPER($E6),(B6*3600+C6*60+D6)/86400) -> 0.01650463 | I6: =IF(OR(A6="",ISNUMBER(A6)),"","X") -> X | J6: Jack Eastman-Nye
A7: =IF(J7="","",_xlfn.XLOOKUP(J7,ClubNames,ClubNumbers,_xlfn.XLOOKUP(J7,RoundRobinRiderNames,RoundRobinRiderDecoratedNames,J7))) -> 407 | B7: 0 | C7: 24 | D7: 27 | G7: =IF($A7="","",IF($I7="X",A7,CONCATENATE(VLOOKUP(A7,Competitors!$A$2:$I$650,3, FALSE)," ",VLOOKUP(A7,Competitors!$A$2:$I$650,2,FALSE)))) -> Hans van Nierop | H7: =IF(LEFT($E7,1)="D",UPPER($E7),(B7*3600+C7*60+D7)/86400) -> 0.016979167 | I7: =IF(OR(A7="",ISNUMBER(A7)),"","X") | J7: Hans van Nierop
A8: =IF(J8="","",_xlfn.XLOOKUP(J8,ClubNames,ClubNumbers,_xlfn.XLOOKUP(J8,RoundRobinRiderNames,RoundRobinRiderDecoratedNames,J8))) -> Chris Bradbury | B8: 0 | C8: 24 | D8: 28 | E8: r | G8: =IF($A8="","",IF($I8="X",A8,CONCATENATE(VLOOKUP(A8,Competitors!$A$2:$I$650,3, FALSE)," ",VLOOKUP(A8,Competitors!$A$2:$I$650,2,FALSE)))) -> Chris Bradbury | H8: =IF(LEFT($E8,1)="D",UPPER($E8),(B8*3600+C8*60+D8)/86400) -> 0.016990741 | I8: =IF(OR(A8="",ISNUMBER(A8)),"","X") -> X | J8: Chris Bradbury
A9: =IF(J9="","",_xlfn.XLOOKUP(J9,ClubNames,ClubNumbers,_xlfn.XLOOKUP(J9,RoundRobinRiderNames,RoundRobinRiderDecoratedNames,J9))) -> Paul Beattie | B9: 0 | C9: 25 | D9: 16 | E9: r | G9: =IF($A9="","",IF($I9="X",A9,CONCATENATE(VLOOKUP(A9,Competitors!$A$2:$I$650,3, FALSE)," ",VLOOKUP(A9,Competitors!$A$2:$I$650,2,FALSE)))) -> Paul Beattie | H9: =IF(LEFT($E9,1)="D",UPPER($E9),(B9*3600+C9*60+D9)/86400) -> 0.017546296 | I9: =IF(OR(A9="",ISNUMBER(A9)),"","X") -> X | J9: Paul Beattie
A10: =IF(J10="","",_xlfn.XLOOKUP(J10,ClubNames,ClubNumbers,_xlfn.XLOOKUP(J10,RoundRobinRiderNames,RoundRobinRiderDecoratedNames,J10))) -> Alex Barrowman | B10: 0 | C10: 25 | D10: 19 | E10: r | G10: =IF($A10="","",IF($I10="X",A10,CONCATENATE(VLOOKUP(A10,Competitors!$A$2:$I$650,3, FALSE)," ",VLOOKUP(A10,Competitors!$A$2:$I$650,2,FALSE)))) -> Alex Barrowman | H10: =IF(LEFT($E10,1)="D",UPPER($E10),(B10*3600+C10*60+D10)/86400) -> 0.017581019 | I10: =IF(OR(A10="",ISNUMBER(A10)),"","X") -> X | J10: Alex Barrowman
A11: =IF(J11="","",_xlfn.XLOOKUP(J11,ClubNames,ClubNumbers,_xlfn.XLOOKUP(J11,RoundRobinRiderNames,RoundRobinRiderDecoratedNames,J11))) -> Pete Bradshaw | B11: 0 | C11: 25 | D11: 36 | E11: r | G11: =IF($A11="","",IF($I11="X",A11,CONCATENATE(VLOOKUP(A11,Competitors!$A$2:$I$650,3, FALSE)," ",VLOOKUP(A11,Competitors!$A$2:$I$650,2,FALSE)))) -> Pete Bradshaw | H11: =IF(LEFT($E11,1)="D",UPPER($E11),(B11*3600+C11*60+D11)/86400) -> 0.017777778 | I11: =IF(OR(A11="",ISNUMBER(A11)),"","X") -> X | J11: Pete Bradshaw
A12: =IF(J12="","",_xlfn.XLOOKUP(J12,ClubNames,ClubNumbers,_xlfn.XLOOKUP(J12,RoundRobinRiderNames,RoundRobinRiderDecoratedNames,J12))) -> Diego Patteri | B12: 0 | C12: 25 | D12: 48 | E12: r | G12: =IF($A12="","",IF($I12="X",A12,CONCATENATE(VLOOKUP(A12,Competitors!$A$2:$I$650,3, FALSE)," ",VLOOKUP(A12,Competitors!$A$2:$I$650,2,FALSE)))) -> Diego Patteri | H12: =IF(LEFT($E12,1)="D",UPPER($E12),(B12*3600+C12*60+D12)/86400) -> 0.017916667 | I12: =IF(OR(A12="",ISNUMBER(A12)),"","X") -> X | J12: Diego Patteri
A13: =IF(J13="","",_xlfn.XLOOKUP(J13,ClubNames,ClubNumbers,_xlfn.XLOOKUP(J13,RoundRobinRiderNames,RoundRobinRiderDecoratedNames,J13))) -> Richard Golding | B13: 0 | C13: 25 | D13: 49 | E13: r | G13: =IF($A13="","",IF($I13="X",A13,CONCATENATE(VLOOKUP(A13,Competitors!$A$2:$I$650,3, FALSE)," ",VLOOKUP(A13,Competitors!$A$2:$I$650,2,FALSE)))) -> Richard Golding | H13: =IF(LEFT($E13,1)="D",UPPER($E13),(B13*3600+C13*60+D13)/86400) -> 0.017928241 | I13: =IF(OR(A13="",ISNUMBER(A13)),"","X") -> X | J13: Richard Golding
A14: =IF(J14="","",_xlfn.XLOOKUP(J14,ClubNames,ClubNumbers,_xlfn.XLOOKUP(J14,RoundRobinRiderNames,RoundRobinRiderDecoratedNames,J14))) -> Malcolm Smith | B14: 0 | C14: 25 | D14: 58 | G14: =IF($A14="","",IF($I14="X",A14,CONCATENATE(VLOOKUP(A14,Competitors!$A$2:$I$650,3, FALSE)," ",VLOOKUP(A14,Competitors!$A$2:$I$650,2,FALSE)))) -> Malcolm Smith | H14: =IF(LEFT($E14,1)="D",UPPER($E14),(B14*3600+C14*60+D14)/86400) -> 0.018032407 | I14: =IF(OR(A14="",ISNUMBER(A14)),"","X") -> X | J14: Malcolm Smith
A15: =IF(J15="","",_xlfn.XLOOKUP(J15,ClubNames,ClubNumbers,_xlfn.XLOOKUP(J15,RoundRobinRiderNames,RoundRobinRiderDecoratedNames,J15))) -> Phil Wilkinson (RFW) | B15: 0 | C15: 26 | D15: 18 | G15: =IF($A15="","",IF($I15="X",A15,CONCATENATE(VLOOKUP(A15,Competitors!$A$2:$I$650,3, FALSE)," ",VLOOKUP(A15,Competitors!$A$2:$I$650,2,FALSE)))) -> Phil Wilkinson (RFW) | H15: =IF(LEFT($E15,1)="D",UPPER($E15),(B15*3600+C15*60+D15)/86400) -> 0.018263889 | I15: =IF(OR(A15="",ISNUMBER(A15)),"","X") -> X | J15: Phil Wilkinson
A16: =IF(J16="","",_xlfn.XLOOKUP(J16,ClubNames,ClubNumbers,_xlfn.XLOOKUP(J16,RoundRobinRiderNames,RoundRobinRiderDecoratedNames,J16))) -> Adam Wells (RFW) | B16: 0 | C16: 26 | D16: 40 | G16: =IF($A16="","",IF($I16="X",A16,CONCATENATE(VLOOKUP(A16,Competitors!$A$2:$I$650,3, FALSE)," ",VLOOKUP(A16,Competitors!$A$2:$I$650,2,FALSE)))) -> Adam Wells (RFW) | H16: =IF(LEFT($E16,1)="D",UPPER($E16),(B16*3600+C16*60+D16)/86400) -> 0.018518519 | I16: =IF(OR(A16="",ISNUMBER(A16)),"","X") -> X | J16: Adam Wells
A17: =IF(J17="","",_xlfn.XLOOKUP(J17,ClubNames,ClubNumbers,_xlfn.XLOOKUP(J17,RoundRobinRiderNames,RoundRobinRiderDecoratedNames,J17))) -> Leah Cuthbertson | B17: 0 | C17: 26 | D17: 49 | E17: r | G17: =IF($A17="","",IF($I17="X",A17,CONCATENATE(VLOOKUP(A17,Competitors!$A$2:$I$650,3, FALSE)," ",VLOOKUP(A17,Competitors!$A$2:$I$650,2,FALSE)))) -> Leah Cuthbertson | H17: =IF(LEFT($E17,1)="D",UPPER($E17),(B17*3600+C17*60+D17)/86400) -> 0.018622685 | I17: =IF(OR(A17="",ISNUMBER(A17)),"","X") -> X | J17: Leah Cuthbertson
A18: =IF(J18="","",_xlfn.XLOOKUP(J18,ClubNames,ClubNumbers,_xlfn.XLOOKUP(J18,RoundRobinRiderNames,RoundRobinRiderDecoratedNames,J18))) -> Mark Tomlinson | B18: 0 | C18: 26 | D18: 50 | G18: =IF($A18="","",IF($I18="X",A18,CONCATENATE(VLOOKUP(A18,Competitors!$A$2:$I$650,3, FALSE)," ",VLOOKUP(A18,Competitors!$A$2:$I$650,2,FALSE)))) -> Mark Tomlinson | H18: =IF(LEFT($E18,1)="D",UPPER($E18),(B18*3600+C18*60+D18)/86400) -> 0.018634259 | I18: =IF(OR(A18="",ISNUMBER(A18)),"","X") -> X | J18: Mark Tomlinson
A19: =IF(J19="","",_xlfn.XLOOKUP(J19,ClubNames,ClubNumbers,_xlfn.XLOOKUP(J19,RoundRobinRiderNames,RoundRobinRiderDecoratedNames,J19))) -> 1161 | B19: 0 | C19: 27 | D19: 6 | G19: =IF($A19="","",IF($I19="X",A19,CONCATENATE(VLOOKUP(A19,Competitors!$A$2:$I$650,3, FALSE)," ",VLOOKUP(A19,Competitors!$A$2:$I$650,2,FALSE)))) -> Maciej Suchocki | H19: =IF(LEFT($E19,1)="D",UPPER($E19),(B19*3600+C19*60+D19)/86400) -> 0.018819444 | I19: =IF(OR(A19="",ISNUMBER(A19)),"","X") | J19: Maciej Suchocki
A20: =IF(J20="","",_xlfn.XLOOKUP(J20,ClubNames,ClubNumbers,_xlfn.XLOOKUP(J20,RoundRobinRiderNames,RoundRobinRiderDecoratedNames,J20))) -> John Beckett | B20: 0 | C20: 27 | D20: 56 | G20: =IF($A20="","",IF($I20="X",A20,CONCATENATE(VLOOKUP(A20,Competitors!$A$2:$I$650,3, FALSE)," ",VLOOKUP(A20,Competitors!$A$2:$I$650,2,FALSE)))) -> John Beckett | H20: =IF(LEFT($E20,1)="D",UPPER($E20),(B20*3600+C20*60+D20)/86400) -> 0.019398148 | I20: =IF(OR(A20="",ISNUMBER(A20)),"","X") -> X | J20: John Beckett
A21: =IF(J21="","",_xlfn.XLOOKUP(J21,ClubNames,ClubNumbers,_xlfn.XLOOKUP(J21,RoundRobinRiderNames,RoundRobinRiderDecoratedNames,J21))) -> 1094 | B21: 0 | C21: 28 | D21: 27 | G21: =IF($A21="","",IF($I21="X",A21,CONCATENATE(VLOOKUP(A21,Competitors!$A$2:$I$650,3, FALSE)," ",VLOOKUP(A21,Competitors!$A$2:$I$650,2,FALSE)))) -> Andy Poulton | H21: =IF(LEFT($E21,1)="D",UPPER($E21),(B21*3600+C21*60+D21)/86400) -> 0.019756944 | I21: =IF(OR(A21="",ISNUMBER(A21)),"","X") | J21: Andy Poulton
A22: =IF(J22="","",_xlfn.XLOOKUP(J22,ClubNames,ClubNumbers,_xlfn.XLOOKUP(J22,RoundRobinRiderNames,RoundRobinRiderDecoratedNames,J22))) -> Loz Staples | B22: 0 | C22: 28 | D22: 38 | G22: =IF($A22="","",IF($I22="X",A22,CONCATENATE(VLOOKUP(A22,Competitors!$A$2:$I$650,3, FALSE)," ",VLOOKUP(A22,Competitors!$A$2:$I$650,2,FALSE)))) -> Loz Staples | H22: =IF(LEFT($E22,1)="D",UPPER($E22),(B22*3600+C22*60+D22)/86400) -> 0.019884259 | I22: =IF(OR(A22="",ISNUMBER(A22)),"","X") -> X | J22: Loz Staples
A23: =IF(J23="","",_xlfn.XLOOKUP(J23,ClubNames,ClubNumbers,_xlfn.XLOOKUP(J23,RoundRobinRiderNames,RoundRobinRiderDecoratedNames,J23))) -> 567 | B23: 0 | C23: 28 | D23: 38 | E23: r | G23: =IF($A23="","",IF($I23="X",A23,CONCATENATE(VLOOKUP(A23,Competitors!$A$2:$I$650,3, FALSE)," ",VLOOKUP(A23,Competitors!$A$2:$I$650,2,FALSE)))) -> Lawrence Cox | H23: =IF(LEFT($E23,1)="D",UPPER($E23),(B23*3600+C23*60+D23)/86400) -> 0.019884259 | I23: =IF(OR(A23="",ISNUMBER(A23)),"","X") | J23: Lawrence Cox
A24: =IF(J24="","",_xlfn.XLOOKUP(J24,ClubNames,ClubNumbers,_xlfn.XLOOKUP(J24,RoundRobinRiderNames,RoundRobinRiderDecoratedNames,J24))) -> Ed Watson (Ratae) | B24: 0 | C24: 28 | D24: 49 | E24: r | G24: =IF($A24="","",IF($I24="X",A24,CONCATENATE(VLOOKUP(A24,Competitors!$A$2:$I$650,3, FALSE)," ",VLOOKUP(A24,Competitors!$A$2:$I$650,2,FALSE)))) -> Ed Watson (Ratae) | H24: =IF(LEFT($E24,1)="D",UPPER($E24),(B24*3600+C24*60+D24)/86400) -> 0.020011574 | I24: =IF(OR(A24="",ISNUMBER(A24)),"","X") -> X | J24: ed Watson
A25: =IF(J25="","",_xlfn.XLOOKUP(J25,ClubNames,ClubNumbers,_xlfn.XLOOKUP(J25,RoundRobinRiderNames,RoundRobinRiderDecoratedNames,J25))) -> 1107 | B25: 0 | C25: 29 | D25: 8 | E25: r | G25: =IF($A25="","",IF($I25="X",A25,CONCATENATE(VLOOKUP(A25,Competitors!$A$2:$I$650,3, FALSE)," ",VLOOKUP(A25,Competitors!$A$2:$I$650,2,FALSE)))) -> Milly Pinnock | H25: =IF(LEFT($E25,1)="D",UPPER($E25),(B25*3600+C25*60+D25)/86400) -> 0.020231481 | I25: =IF(OR(A25="",ISNUMBER(A25)),"","X") | J25: Milly Pinnock
A26: =IF(J26="","",_xlfn.XLOOKUP(J26,ClubNames,ClubNumbers,_xlfn.XLOOKUP(J26,RoundRobinRiderNames,RoundRobinRiderDecoratedNames,J26))) -> Carolyn Pfalzgraf | B26: 0 | C26: 29 | D26: 13 | G26: =IF($A26="","",IF($I26="X",A26,CONCATENATE(VLOOKUP(A26,Competitors!$A$2:$I$650,3, FALSE)," ",VLOOKUP(A26,Competitors!$A$2:$I$650,2,FALSE)))) -> Carolyn Pfalzgraf | H26: =IF(LEFT($E26,1)="D",UPPER($E26),(B26*3600+C26*60+D26)/86400) -> 0.020289352 | I26: =IF(OR(A26="",ISNUMBER(A26)),"","X") -> X | J26: Carolyn Pfalzgraf
A27: =IF(J27="","",_xlfn.XLOOKUP(J27,ClubNames,ClubNumbers,_xlfn.XLOOKUP(J27,RoundRobinRiderNames,RoundRobinRiderDecoratedNames,J27))) -> Mike Deely | B27: 0 | C27: 29 | D27: 55 | E27: r | G27: =IF($A27="","",IF($I27="X",A27,CONCATENATE(VLOOKUP(A27,Competitors!$A$2:$I$650,3, FALSE)," ",VLOOKUP(A27,Competitors!$A$2:$I$650,2,FALSE)))) -> Mike Deely | H27: =IF(LEFT($E27,1)="D",UPPER($E27),(B27*3600+C27*60+D27)/86400) -> 0.020775463 | I27: =IF(OR(A27="",ISNUMBER(A27)),"","X") -> X | J27: Mike Deely
A28: David Morgan | B28: 0 | C28: 29 | D28: 58 | G28: =IF($A28="","",IF($I28="X",A28,CONCATENATE(VLOOKUP(A28,Competitors!$A$2:$I$650,3, FALSE)," ",VLOOKUP(A28,Competitors!$A$2:$I$650,2,FALSE)))) -> David Morgan | H28: =IF(LEFT($E28,1)="D",UPPER($E28),(B28*3600+C28*60+D28)/86400) -> 0.020810185 | I28: =IF(OR(A28="",ISNUMBER(A28)),"","X") -> X | J28: David Morgan
A29: =IF(J29="","",_xlfn.XLOOKUP(J29,ClubNames,ClubNumbers,_xlfn.XLOOKUP(J29,RoundRobinRiderNames,RoundRobinRiderDecoratedNames,J29))) -> Philip Merritt | B29: 0 | C29: 30 | D29: 17 | G29: =IF($A29="","",IF($I29="X",A29,CONCATENATE(VLOOKUP(A29,Competitors!$A$2:$I$650,3, FALSE)," ",VLOOKUP(A29,Competitors!$A$2:$I$650,2,FALSE)))) -> Philip Merritt | H29: =IF(LEFT($E29,1)="D",UPPER($E29),(B29*3600+C29*60+D29)/86400) -> 0.021030093 | I29: =IF(OR(A29="",ISNUMBER(A29)),"","X") -> X | J29: Philip Merritt
A30: =IF(J30="","",_xlfn.XLOOKUP(J30,ClubNames,ClubNumbers,_xlfn.XLOOKUP(J30,RoundRobinRiderNames,RoundRobinRiderDecoratedNames,J30))) -> David Creese | B30: 0 | C30: 30 | D30: 19 | G30: =IF($A30="","",IF($I30="X",A30,CONCATENATE(VLOOKUP(A30,Competitors!$A$2:$I$650,3, FALSE)," ",VLOOKUP(A30,Competitors!$A$2:$I$650,2,FALSE)))) -> David Creese | H30: =IF(LEFT($E30,1)="D",UPPER($E30),(B30*3600+C30*60+D30)/86400) -> 0.021053241 | I30: =IF(OR(A30="",ISNUMBER(A30)),"","X") -> X | J30: David Creese
A31: =IF(J31="","",_xlfn.XLOOKUP(J31,ClubNames,ClubNumbers,_xlfn.XLOOKUP(J31,RoundRobinRiderNames,RoundRobinRiderDecoratedNames,J31))) -> Isaac Barral | B31: 0 | C31: 30 | D31: 36 | G31: =IF($A31="","",IF($I31="X",A31,CONCATENATE(VLOOKUP(A31,Competitors!$A$2:$I$650,3, FALSE)," ",VLOOKUP(A31,Competitors!$A$2:$I$650,2,FALSE)))) -> Isaac Barral | H31: =IF(LEFT($E31,1)="D",UPPER($E31),(B31*3600+C31*60+D31)/86400) -> 0.02125 | I31: =IF(OR(A31="",ISNUMBER(A31)),"","X") -> X | J31: Isaac Barral
A32: =IF(J32="","",_xlfn.XLOOKUP(J32,ClubNames,ClubNumbers,_xlfn.XLOOKUP(J32,RoundRobinRiderNames,RoundRobinRiderDecoratedNames,J32))) -> Bethany Spencer | B32: 0 | C32: 31 | D32: 20 | G32: =IF($A32="","",IF($I32="X",A32,CONCATENATE(VLOOKUP(A32,Competitors!$A$2:$I$650,3, FALSE)," ",VLOOKUP(A32,Competitors!$A$2:$I$650,2,FALSE)))) -> Bethany Spencer | H32: =IF(LEFT($E32,1)="D",UPPER($E32),(B32*3600+C32*60+D32)/86400) -> 0.021759259 | I32: =IF(OR(A32="",ISNUMBER(A32)),"","X") -> X | J32: Bethany Spencer
A33: =IF(J33="","",_xlfn.XLOOKUP(J33,ClubNames,ClubNumbers,_xlfn.XLOOKUP(J33,RoundRobinRiderNames,RoundRobinRiderDecoratedNames,J33))) -> Noel Toone | B33: 0 | C33: 31 | D33: 20 | E33: r | G33: =IF($A33="","",IF($I33="X",A33,CONCATENATE(VLOOKUP(A33,Competitors!$A$2:$I$650,3, FALSE)," ",VLOOKUP(A33,Competitors!$A$2:$I$650,2,FALSE)))) -> Noel Toone | H33: =IF(LEFT($E33,1)="D",UPPER($E33),(B33*3600+C33*60+D33)/86400) -> 0.021759259 | I33: =IF(OR(A33="",ISNUMBER(A33)),"","X") -> X | J33: Noel Toone
A34: =IF(J34="","",_xlfn.XLOOKUP(J34,ClubNames,ClubNumbers,_xlfn.XLOOKUP(J34,RoundRobinRiderNames,RoundRobinRiderDecoratedNames,J34))) -> Hayley Moore | B34: 0 | C34: 32 | D34: 1 | E34: r | G34: =IF($A34="","",IF($I34="X",A34,CONCATENATE(VLOOKUP(A34,Competitors!$A$2:$I$650,3, FALSE)," ",VLOOKUP(A34,Competitors!$A$2:$I$650,2,FALSE)))) -> Hayley Moore | H34: =IF(LEFT($E34,1)="D",UPPER($E34),(B34*3600+C34*60+D34)/86400) -> 0.022233796 | I34: =IF(OR(A34="",ISNUMBER(A34)),"","X") -> X | J34: Hayley Moore
A35: =IF(J35="","",_xlfn.XLOOKUP(J35,ClubNames,ClubNumbers,_xlfn.XLOOKUP(J35,RoundRobinRiderNames,RoundRobinRiderDecoratedNames,J35))) -> 674 | B35: 0 | C35: 32 | D35: 7 | G35: =IF($A35="","",IF($I35="X",A35,CONCATENATE(VLOOKUP(A35,Competitors!$A$2:$I$650,3, FALSE)," ",VLOOKUP(A35,Competitors!$A$2:$I$650,2,FALSE)))) -> Jennifer Clegg | H35: =IF(LEFT($E35,1)="D",UPPER($E35),(B35*3600+C35*60+D35)/86400) -> 0.022303241 | I35: =IF(OR(A35="",ISNUMBER(A35)),"","X") | J35: Jennifer Clegg
A36: =IF(J36="","",_xlfn.XLOOKUP(J36,ClubNames,ClubNumbers,_xlfn.XLOOKUP(J36,RoundRobinRiderNames,RoundRobinRiderDecoratedNames,J36))) -> Martin Webb | B36: 0 | C36: 33 | D36: 6 | G36: =IF($A36="","",IF($I36="X",A36,CONCATENATE(VLOOKUP(A36,Competitors!$A$2:$I$650,3, FALSE)," ",VLOOKUP(A36,Competitors!$A$2:$I$650,2,FALSE)))) -> Martin Webb | H36: =IF(LEFT($E36,1)="D",UPPER($E36),(B36*3600+C36*60+D36)/86400) -> 0.022986111 | I36: =IF(OR(A36="",ISNUMBER(A36)),"","X") -> X | J36: Martin Webb
A37: =IF(J37="","",_xlfn.XLOOKUP(J37,ClubNames,ClubNumbers,_xlfn.XLOOKUP(J37,RoundRobinRiderNames,RoundRobinRiderDecoratedNames,J37))) -> Maria Cayford | B37: 0 | C37: 33 | D37: 42 | G37: =IF($A37="","",IF($I37="X",A37,CONCATENATE(VLOOKUP(A37,Competitors!$A$2:$I$650,3, FALSE)," ",VLOOKUP(A37,Competitors!$A$2:$I$650,2,FALSE)))) -> Maria Cayford | H37: =IF(LEFT($E37,1)="D",UPPER($E37),(B37*3600+C37*60+D37)/86400) -> 0.023402778 | I37: =IF(OR(A37="",ISNUMBER(A37)),"","X") -> X | J37: Maria Cayford
